Workbook

Sheet Modelo de dominio
A1: Ir al listado de objetos de dominio >>

Sheet Modelo de dominio anémico
A1: Ir al listado de objetos de dominio >>

Sheet ListadoObjetosDominio
A1: <<Ir al modelo de dominio
A2: Línea de vida | B2: Nombre | C2: Descripción | D2: Muestreo de datos | E2: Caracterización objeto
A3: 1 | B3: Cliente | C3: Objeto de dominio que representa a cada uno de los usuarios registrados que realizan compras en la plataforma de Imexcol. | D3: Ir | E3: Ir
A4: 2 | B4: Administrador | C4: Objeto de dominio que representa al personal interno encargado de gestionar el catálogo, los pedidos y la operación general del sistema. | D4: Ir | E4: Ir
A5: 3 | B5: Dirección | C5: Objeto de dominio que representa la ubicación física y estructurada que registra un cliente para la entrega de sus productos o propósitos de facturación. | D5: Ir | E5: Ir
A6: 4 | B6: Categoría | C6: Objeto de dominio que representa a cada una de las agrupaciones taxonómicas en las que se organizan los productos del catálogo de Imexcol. | D6: Ir | E6: Ir
A7: 5 | B7: Producto | C7: Objeto de dominio que representa a cada uno de los artículos de importación (bolsos, juguetes, etc.) que están disponibles para la venta en la tienda. | D7: Ir | E7: Ir
A8: 6 | B8: ImagenProducto | C8: Objeto de dominio que representa a cada uno de los recursos visuales o fotografías asociadas a un producto para su exhibición. | D8: Ir | E8: Ir
A9: 7 | B9: Reseña | C9: Objeto de dominio que representa a cada una de las calificaciones y comentarios dejados por un cliente sobre un producto específico que ya ha comprado. | D9: Ir | E9: Ir
A10: 8 | B10: CarritoCompras | C10: Objeto de dominio que representa la sesión temporal donde un cliente agrupa los productos que tiene intención de adquirir antes de formalizar la transacción. | D10: Ir | E10: Ir
A11: 9 | B11: ItemCarrito | C11: Objeto de dominio que representa a cada una de las selecciones individuales (producto específico y cantidad) dentro del carrito activo de un cliente. | D11: Ir | E11: Ir
A12: 10 | B12: Pedido | C12: Objeto de dominio que representa la confirmación formal, transaccional y definitiva de una compra realizada por un cliente en Imexcol. | D12: Ir | E12: Ir
A13: 11 | B13: LineaPedido | C13: Objeto de dominio que representa el detalle individual de un pedido, permitiendo registrar de forma histórica cada producto adquirido, su cantidad y su valor al momento de confirmar la compra. (Evidencia histórica de la compra) | D13: Ir | E13: Ir
A14: 12 | B14: Pago | C14: Objeto de dominio que representa el registro de la transacción financiera procesada a través de la pasarela de pagos para saldar un pedido. | D14: Ir | E14: Ir
... A18: 16 | B18: EventoRastreo | C18: Objeto de dominio que representa a cada una de las actualizaciones o hitos temporales (ej. en preparación, en tránsito, entregado) que ocurren durante el ciclo de vida de un envío. | D18: Ir | E18: Ir

Sheet M-Cliente
A1: << Ir al modelo de dominio | I1: << Ir a la caracterización del objeto de dominio
F2: << Ir al listado de objetos de dominio
A3: Nombre | B3: =ListadoObjetosDominio!B3
A4: Descripción | B4: =ListadoObjetosDominio!C3
A5: Identificador único universal (UUID) del cliente, generado automáticamente al registrarse. | B5: Representa el nombre o nombres del cliente. | C5: Representa el apellido o apellidos del cliente. | D5: Representa el correo electrónico único de contacto y autenticación del cliente. | E5: Contraseña del cliente almacenada de forma segura para autenticación. | F5: Número de teléfono de contacto del cliente (opcional). | G5: Indica si el cliente está activo (true) o inactivo (false) en el sistema.
A6: id | B6: nombre | C6: apellido | D6: correoElectronico | E6: contrasena | F6: telefono | G6: estado
A7: 3F2504E0-4F89-11D3-9A0C-0305E82C3301 | B7: Carlos | C7: Restrepo | D7: carlos.restrepo@imexcol.com | E7: ******** | F7: 3001112233 | G7: TRUE
A8: 3F2504E0-4F89-11D3-9A0C-0305E82C3302 | B8: María | C8: González | D8: maria.gonzalez@imexcol.com | E8: ******** | F8: 3104445566 | G8: TRUE
A9: 3F2504E0-4F89-11D3-9A0C-0305E82C3303 | B9: Andrés | C9: Mejía | D9: andres.mejia@imexcol.com | E9: ******** | F9: 3207778899 | G9: TRUE
A10: 3F2504E0-4F89-11D3-9A0C-0305E82C3304 | B10: Camila | C10: Ramírez | D10: camila.ramirez@imexcol.com | E10: ******** | F10: 3151231234 | G10: TRUE
A11: 3F2504E0-4F89-11D3-9A0C-0305E82C3305 | B11: Daniel | C11: Pérez | D11: daniel.perez@imexcol.com | E11: ******** | F11: 3009998877 | G11: FALSE
A14: Corresponde a los datos generales del objeto de dominio (nombre, descripción)
A15: Corresponde a las descripciones de los atributos
A16: Coresponde al nombre de los atributos
A17: Corresponde a los datos que son de libre ingreso
A18: Corresponde a los datos que se generarán automáticamente (idCliente)
A19: Corresponde a la combinación única 1
A20: Corresponde a la combinación única 2

Sheet C-Cliente
A1: << Ir al modelo de dominio | D1: << Ir al listado de objetos de dominio | G1: << Ir a la caracterización del objeto de dominio
A2: Nombre | B2: ='M-Cliente'!B3
A3: Descripción | B3: ='M-Cliente'!B4
A4: Nombre atributo | B4: Descripción atributo | C4: Identificador del objeto de dominio | D4: Tipo de dato | E4: Obligatorio | F4: Longitud minima(si aplica longitud maxima(si aplica) | G4: Longitud maxima(si aplica longitud maxima(si aplica) | H4: Precisión (si aplica) | I4: Redondeo(si aplica) | J4: Rango inicial(si aplica) | K4: Rango final (si aplica) | L4: Formato(Si aplica) | M4: Reglas especiales(si aplica) | N4: Dato calculado | O4: Aplica ajuste del dato(si aplica) | P4: Carácter de ajuste(si aplica) | Q4: Quitar espacios en blanco al inicio(si aplica) | R4: Quitar espacios en blanco al fin(si aplica) | S4: Dato sensible(si aplica) | T4: Valor por defecto(si aplica) | U4: Auto generado
A5: ='M-Cliente'!A6 | B5: ='M-Cliente'!A5 | C5: Si | D5: Alfanumerico | E5: Si | F5: 1 | G5: 20 | L5: Mayusculas | N5: No | O5: No | Q5: Si | R5: Si | S5: No | U5: Si
A6: ='M-Cliente'!B6 | B6: ='M-Cliente'!B5 | C6: No | D6: Caracter | E6: Si | F6: 2 | G6: 2 | L6: Mayusculas | M6: Solo valores: CC, CE, NIT, TI | N6: No | O6: Si | P6: Espacio | Q6: Si | R6: Si | S6: No | T6: CC | U6: No
A7: ='M-Cliente'!C6 | B7: ='M-Cliente'!D5 | C7: No | D7: Alfanumerico | E7: Si | F7: 5 | G7: 20 | M7: Solo caracteres alfanuméricos | N7: No | O7: No | Q7: Si | R7: Si | S7: Si | U7: No
A8: ='M-Cliente'!D6 | B8: ='M-Cliente'!D5 | C8: No | D8: Texto | E8: Si | F8: 3 | G8: 150 | L8: Capitalizado | N8: No | O8: No | Q8: Si | R8: Si | S8: No | U8: No
A9: ='M-Cliente'!E6 | B9: ='M-Cliente'!E5 | C9: No | D9: Alfanumerico | E9: Si | F9: 5 | G9: 100 | L9: email | M9: Debe contener '@' y dominio válido | N9: No | O9: No | Q9: Si | R9: Si | S9: Si | U9: No
A10: ='M-Cliente'!F6 | B10: ='M-Cliente'!F5 | C10: No | D10: Numerico | E10: Si | F10: 10 | G10: 10 | N10: No | O10: No | Q10: No | R10: No | S10: Si | U10: No
A12: Nombre combinación unica | B12: Descripción | C12: Atributos involucrados
A13: ='M-Cliente'!G6 | B13: ='M-Cliente'!G5 | C13: ='M-Cliente'!E6
A14: ='M-Cliente'!H6 | B14: ='M-Cliente'!H5 | C14: ='M-Cliente'!B6 | D14: ='M-Cliente'!C6
A16: Responsabilidad | B16: Descripción | C16: Entradas | F16: Salida | H16: Políticas (Reglas de Negocio) | J16: Excepción
C17: Parámetro | D17: Tipo de dato | E17: Descripción | F17: Tipo de Dato | G17: Descripción | H17: Política | I17: Descripción | J17: Detalle | K17: ¿Qué hago?
A18: ='E-Cliente'!B7 | B18: ='E-Cliente'!C7 | C18: clienteNuevo | D18: Cliente | E18: Contiene la información del cliente que se va a registrar. | F18: Logico | G18: Retorna verdadero si el cliente se registró y guardó correctamente. | H18: ='E-Cliente'!G7 | I18: ='E-Cliente'!H7 | J18: Generar una excepción indicando que se violó la regla: el correo y el teléfono deben ser obligatorios y tener formato válido. | K18: Detener operación
H19: ='E-Cliente'!G8 | I19: ='E-Cliente'!H8 | J19: Generar excepción indicando que el correo ingresado ya se encuentra registrado por otro usuario. | K19: Detener operación
H20: ='E-Cliente'!G9 | I20: ='E-Cliente'!H9 | J20: Generar excepción indicando que el documento ya está registrado por otro usuario. | K20: Detener operación
A21: ='E-Cliente'!B10 | B21: {='E-Cliente'!C10:C10} | C21: clienteModificado | D21: Cliente | E21: Contiene la nueva información del cliente a actualizar. | F21: Logico | G21: Retorna verdadero si la información se actualizó con éxito en la base de datos. | H21: ='E-Cliente'!G10 | I21: ='E-Cliente'!H10 | J21: Generar excepción indicando que el cliente que se intenta modificar no existe. | K21: Detener operación
A22: ='E-Cliente'!B11 | B22: ='E-Cliente'!C11 | C22: filtros | D22: Texto | E22: Parámetros opcionales para filtrar la búsqueda de clientes. | F22: Lista<Cliente> | G22: Retorna una colección con los objetos de los clientes encontrados. | H22: ='E-Cliente'!G11 | I22: ='E-Cliente'!H11 | J22: Generar excepción indicando acceso denegado por falta de permisos administrativos | K22: Detener operación

Sheet E-Cliente
A1: << Ir al modelo de dominio | E1: << Ir al listado de objetos de dominio | I1: << Ir a la caracterización del objeto de dominio
A2: Objeto de Dominio: | B2: =ListadoObjetosDominio!B3
A3: Descripción: | B3: =ListadoObjetosDominio!C3
A4: Actor | B4: Action/Command | D4: Entity/Aggregate/Object domain | E4: Read Model | G4: Business Rule/Policy | I4: External System | J4: Domain Event | K4: Hotspot/questions/Risk
A5: Actor | B5: Acción | C5: Descripción | D5: Objeto de dominio | E5: Información externa | G5: Políticas | I5: Sistema Externo | J5: Evento | K5: Aspectos por solucionar
E6: Información | F6: Descripción | G6: Número | H6: Descripción
A7: =ListadoObjetosDominio!B3 | B7: Registrar información del cliente | C7: Crear una nueva cuenta de usuario en la plataforma de comercio electrónico de Imexcol para poder realizar compras. | D7: =ListadoObjetosDominio!B3 | E7: tipoDocumento, numeroDocumento, nombre, correo, telefono | F7: Datos mínimos obligatorios requeridos por el sistema para identificar al usuario, facturar y contactarlo. | G7: CLI-POL-01 | H7: Asegurar que los datos requeridos sean válidos a nivel de tipo de dato, formato, rango, longitud y obligatoriedad. | I7: Base de datos | J7: Cliente registrado exitosamente | K7: Riesgo de que el usuario ingrese correos electrónicos temporales o falsos que reboten las facturas.
G8: CLI-POL-02 | H8: El correo electrónico ingresado no debe existir previamente en el sistema (Combinación única 1).
G9: CLI-POL-03 | H9: La combinación de tipo de documento y número de documento no debe existir previamente en el sistema (Combinación única 2).
A10: =_xlfn.CONCAT(ListadoObjetosDominio!B3,"/ ",ListadoObjetosDominio!B4,) | B10: Modificar datos del cliente | C10: Actualizar la información personal de contacto (teléfono o nombre) del usuario registrado en el sistema. | D10: =ListadoObjetosDominio!B3 | E10: idCliente, nombre, telefono | F10: Información editable del perfil del usuario para mantener el contacto actualizado en futuros despachos. | G10: CLI-POL-04 | H10: El identificador del cliente (idCliente) proporcionado debe existir obligatoriamente en el sistema. | I10: Base de datos | J10: Datos de cliente modificados | K10: Un administrador podría cambiar por error el teléfono de un cliente justo antes de un despacho logístico.
A11: =ListadoObjetosDominio!B4 | B11: Consultar listado de clientes | C11: Listar en el panel de control todos los usuarios registrados para gestión operativa y soporte. | D11: =ListadoObjetosDominio!B3 | E11: idCliente, tipoDocumento, numeroDocumento, nombre, correo, telefono | F11: Visualización tabular completa de los datos del cliente para que el administrador pueda auditar el registro. | G11: CLI-POL-05 | H11: El administrador que ejecuta la acción debe tener una sesión válida y activa en el sistema. | I11: Base de datos | J11: Listado de clientes consultado | K11: Si la base de datos crece a miles de clientes, la consulta sin paginación podría saturar la memoria del servidor (TimeOut).

Sheet M-Administrador
A1: << Ir al modelo de dominio | D1: << Ir al listado de objetos de dominio | G1: << Ir a la caracterización del objeto de dominio
A2: Nombre | B2: =ListadoObjetosDominio!B4
A3: Descripción | B3: =ListadoObjetosDominio!C4
A4: Identificador único universal (UUID) del administrador. | B4: Nombre de usuario único del administrador para iniciar sesión. | C4: Correo electrónico de contacto del administrador. | D4: Contraseña del administrador almacenada de forma segura. | E4: Indica si el administrador está activo (true) o inactivo (false).
A5: id | B5: nombreUsuario | C5: correoElectronico | D5: contrasena | E5: estado
A6: A1B2C3D4-5566-4F77-8899-AABBCCDDEE01 | B6: admin.principal | C6: admin@imexcol.com | D6: ******** | E6: TRUE
A7: A1B2C3D4-5566-4F77-8899-AABBCCDDEE02 | B7: lmartinez | C7: l.martinez@imexcol.com | D7: ******** | E7: TRUE
A8: A1B2C3D4-5566-4F77-8899-AABBCCDDEE03 | B8: sgomez | C8: s.gomez@imexcol.com | D8: ******** | E8: TRUE
A9: A1B2C3D4-5566-4F77-8899-AABBCCDDEE04 | B9: alopez | C9: a.lopez@imexcol.com | D9: ******** | E9: FALSE
A10: A1B2C3D4-5566-4F77-8899-AABBCCDDEE05 | B10: mcastro | C10: m.castro@imexcol.com | D10: ******** | E10: TRUE
A13: Corresponde a los datos generales del objeto de dominio (nombre, descripción)
A14: Corresponde a las descripciones de los atributos
A15: Coresponde al nombre de los atributos
A16: Corresponde a los datos que son de libre ingreso
A17: Corresponde a los datos que se generarán automáticamente (IdAdmin)
A18: Corresponde a la combinación única 1

Sheet C-Administrador
A1: << Ir al modelo de dominio | D1: << Ir al listado de objetos de dominio | G1: << Ir a la caracterización del objeto de dominio
A2: Nombre | B2: ='M-Administrador'!B2
A3: Descripción | B3: ='M-Administrador'!B3
A4: Nombre atributo | B4: Descripción atributo | C4: Identificador del objeto de dominio | D4: Tipo de dato | E4: Obligatorio | F4: Longitud minima(si aplica longitud maxima(si aplica) | G4: Longitud maxima(si aplica longitud maxima(si aplica) | H4: Precisión (si aplica) | I4: Redondeo(si aplica) | J4: Rango inicial(si aplica) | K4: Rango final (si aplica) | L4: Formato(Si aplica) | M4: Reglas especiales(si aplica) | N4: Dato calculado | O4: Aplica ajuste del dato(si aplica) | P4: Carácter de ajuste(si aplica) | Q4: Quitar espacios en blanco al inicio(si aplica) | R4: Quitar espacios en blanco al fin(si aplica) | S4: Dato sensible(si aplica) | T4: Valor por defecto(si aplica) | U4: Auto generado
A5: ='M-Administrador'!A5 | B5: ='M-Administrador'!A4 | C5: Si | D5: Numerico entero | E5: Si | J5: 1 | K5: 999999 | M5: Identificador secuencial del administrador | N5: No | S5: No | U5: Si
A6: ='M-Administrador'!B5 | B6: ='M-Administrador'!B4 | C6: No | D6: Alfanumerico | E6: Si | F6: 5 | G6: 30 | L6: Minusculas | M6: No debe contener espacios ni caracteres especiales | N6: No | O6: No | Q6: Si | R6: Si | S6: No | U6: No
A7: ='M-Administrador'!C5 | B7: ='M-Administrador'!C4 | C7: No | D7: Texto | E7: Si | F7: 8 | G7: 255 | M7: Debe almacenarse encriptada por seguridad del sistema | N7: No | O7: No | Q7: No | R7: No | S7: Si | U7: No
A9: Nombre combinación unica | B9: Descripción | C9: Atributos involucrados
A10: ='M-Administrador'!D5 | B10: ='M-Administrador'!D4 | C10: ='M-Administrador'!B5
A12: Responsabilidad | B12: Descripción | C12: Entradas | F12: Salida | H12: Políticas (Reglas de Negocio) | J12: Excepción
C13: Parámettro | D13: Tipo de dato | E13: Descripci | F13: Tipo de Dato | G13: Descripción | H13: Política | I13: Descripción | J13: Detalle | K13: ¿Qué hago?
A14: ='E-Administrador'!B7 | B14: ='E-Administrador'!C7 | C14: adminNuevo | D14: Administrador | E14: Contiene la información del administrador que se va a registrar. | F14: Logico | G14: Retorna verdadero si el administrador se registró correctamente. | H14: ='E-Administrador'!G7 | I14: ='E-Administrador'!H7 | J14: Generar excepción indicando qué campo no cumple con el formato o es obligatorio. | K14: Detener operación
H15: ='E-Administrador'!G8 | I15: ='E-Administrador'!H8 | J15: Generar excepción indicando que el nombre de usuario ya se encuentra en uso por otro empleado. | K15: Detener operación
A17: ='E-Administrador'!B9 | B17: ='E-Administrador'!C9 | C17: adminModificado | D17: Administrador | E17: Contiene el identificador y la nueva credencial a actualizar. | F17: Logico | G17: Retorna verdadero si la contraseña se actualizó con éxito en la base de datos. | H17: ='E-Administrador'!G9 | I17: ='E-Administrador'!H9 | J17: Generar excepción indicando que el administrador que se intenta modificar no existe. | K17: Detener operación
A18: ='E-Administrador'!B10 | B18: ='E-Administrador'!C10 | C18: idAdmin | D18: alfanumerico | E18: Identificador exacto del administrador al que se le retirarán los privilegios. | F18: Logico | G18: Retorna verdadero si el administrador fue eliminado correctamente. | H18: ='E-Administrador'!G10 | I18: ='E-Administrador'!H10 | J18: Generar excepción indicando que el administrador a eliminar no se encuentra registrado. | K18: Detener operación
H19: ='E-Administrador'!G11 | I19: ='E-Administrador'!H11 | J19: Generar excepción indicando que no se puede eliminar al último administrador del sistema. | K19: Detener operación
A20: ='E-Administrador'!B12 | B20: ='E-Administrador'!C12 | C20: credenciales | D20: Administrador | E20: Contiene el usuario y la contraseña que el empleado intenta validar. | F20: Logico | G20: Retorna verdadero si la autenticación fue exitosa. | H20: ='E-Administrador'!G12 | I20: ='E-Administrador'!H12 | J20: Generar excepción indicando que el nombre de usuario o la contraseña son incorrectos. | K20: Detener operación
A21: ='E-Administrador'!B13 | B21: ='E-Administrador'!C13 | C21: filtros | D21: Texto | E21: Parámetros opcionales para filtrar la búsqueda de empleados. | F21: Lista<Administrador> | G21: Retorna una colección con los objetos de los administradores encontrados. | H21: ='E-Administrador'!G13 | I21: ='E-Administrador'!H13 | J21: Generar excepción indicando acceso denegado por sesión inactiva o falta de permisos. | K21: Detener operación

Sheet E-Administrador
A1: << Ir al modelo de dominio | E1: << Ir al listado de objetos de dominio | I1: << Ir a la caracterización del objeto de dominio
A2: Objeto de Dominio: | B2: =ListadoObjetosDominio!B4
A3: Descripción: | B3: =ListadoObjetosDominio!C4
A4: Actor | B4: Action/Command | D4: Entity/Aggregate/Object domain | E4: Read Model | G4: Business Rule/Policy | I4: External System | J4: Domain Event | K4: Hotspot/questions/Risk
A5: Actor | B5: Acción | C5: Descripción | D5: Objeto de dominio | E5: Información externa | G5: Políticas | I5: Sistema Externo | J5: Evento | K5: Aspectos por solucionar
E6: Información | F6: Descripción | G6: Número | H6: Descripción
A7: =ListadoObjetosDominio!B4 | B7: Registrar nuevo administrador | C7: Crear un nuevo usuario con credenciales para que un empleado pueda ingresar al panel de control de Imexcol. | D7: =ListadoObjetosDominio!B4 | E7: usuario, password | F7: Credenciales de acceso requeridas para autenticar al nuevo empleado en el sistema. | G7: ADM-POL-01 | H7: Asegurar que los datos requeridos sean válidos a nivel de tipo de dato, formato, rango, longitud y obligatoriedad | I7: Base de datos | J7: Administrador registrado | K7: Riesgo de que la contraseña asignada inicialmente sea muy débil o predecible (ej. 12345678).
G8: ADM-POL-02 | H8: El nombre de usuario ingresado no debe existir previamente en el sistema (Combinación única 1).
A9: =ListadoObjetosDominio!B4 | B9: Modificar contraseña | C9: Actualizar la clave de acceso de un administrador existente por motivos de seguridad o bloqueo. | D9: =ListadoObjetosDominio!B4 | E9: idAdmin, password | F9: Identificador del empleado y la nueva credencial de seguridad a actualizar. | G9: ADM-POL-03 | H9: El idAdmin proporcionado debe existir obligatoriamente en el sistema. | I9: Base de datos | J9: Contraseña de administrador modificada | K9: Contraseña de administrador modificada Si un administrador cambia la contraseña de otro sin autorización, podría generar un bloqueo operativo en la tienda.
A10: =ListadoObjetosDominio!B4 | B10: Eliminar administrador | C10: Revocar el acceso de un empleado al sistema eliminando su registro de la base de datos | D10: =ListadoObjetosDominio!B4 | E10: idAdmin | F10: Identificador exacto del empleado al que se le retirarán los privilegios de acceso. | G10: ADM-POL-04 | H10: El idAdmin a eliminar debe existir previamente en la base de datos. | I10: Base de datos | J10: Administrador eliminado | K10: Riesgo de que el último o único administrador del sistema sea eliminado, bloqueando el acceso total a la plataforma.
G11: ADM-POL-05 | H11: El sistema debe impedir la eliminación si el usuario a borrar es el único administrador restante en la base de datos.
A12: =ListadoObjetosDominio!B4 | B12: Iniciar sesión (Autenticar) | C12: Validar las credenciales del empleado para otorgarle acceso seguro al panel de control del e-commerce | D12: =ListadoObjetosDominio!B4 | E12: usuario, password | F12: Formulario de login donde el empleado ingresa sus credenciales de acceso. | G12: ADM-POL-06 | H12: El usuario y la contraseña ingresados deben coincidir exactamente con un registro existente en la base de datos. | I12: Sistema Auth | J12: Sesión de administrador iniciada | K12: Riesgo de ataques de fuerza bruta (intentar adivinar la clave repetidamente). ¿Se debería bloquear el usuario tras 3 intentos fallidos?
A13: =ListadoObjetosDominio!B4 | B13: Consultar administradores | C13: Listar todos los empleados que actualmente tienen acceso al panel administrativo del e-commerce. | D13: =ListadoObjetosDominio!B4 | E13: idAdmin, usuario | F13: Vista de auditoría para revisar quiénes tienen credenciales activas en el sistema. | G13: ADM-POL-07 | H13: El administrador que ejecuta la consulta debe contar con una sesión activa en el sistema. | I13: Base de datos | J13: Listado de administradores consultado | K13: Exposición de nombres de usuario a empleados que no deberían tener permisos de auditoría de personal.

Sheet M-Dirección
A1: << Ir al modelo de dominio | I1: << Ir al listado de objetos de dominio | L1: << Ir a la caracterización del objeto de dominio
A2: Nombre: | B2: =ListadoObjetosDominio!B5
A3: Descripción: | B3: =ListadoObjetosDominio!C5
A4: Identificador único universal (UUID) de la dirección. | B4: Referencia al cliente al que pertenece esta dirección. | C4: Nomenclatura exacta de la dirección (calle, carrera, número). | D4: Ciudad o municipio donde se ubica la dirección. | E4: Departamento o estado donde se ubica la dirección. | F4: País donde se ubica la dirección. | G4: Código postal de la dirección (opcional). | H4: Indica si esta es la dirección principal del cliente (true/false).
A5: id | B5: cliente | C5: calle | D5: ciudad | E5: departamento | F5: pais | G5: codigoPostal | H5: esPrincipal
A6: D1234567-8901-4234-5678-90123456D001 | B6: 3F2504E0-4F89-11D3-9A0C-0305E82C3301 | C6: Calle 10 # 43-20 | D6: Medellín | E6: Antioquia | F6: Colombia | G6: 050021 | H6: TRUE
A7: D1234567-8901-4234-5678-90123456D002 | B7: 3F2504E0-4F89-11D3-9A0C-0305E82C3302 | C7: Carrera 48 # 32-15 | D7: Envigado | E7: Antioquia | F7: Colombia | G7: 055422 | H7: FALSE
A8: D1234567-8901-4234-5678-90123456D003 | B8: 3F2504E0-4F89-11D3-9A0C-0305E82C3303 | C8: Carrera 15 # 85-30 | D8: Bogotá | E8: Cundinamarca | F8: Colombia | G8: 110221 | H8: TRUE
A9: D1234567-8901-4234-5678-90123456D004 | B9: 3F2504E0-4F89-11D3-9A0C-0305E82C3304 | C9: Avenida 6N # 24-10 | D9: Cali | E9: Valle del Cauca | F9: Colombia | G9: 760045 | H9: TRUE
A10: D1234567-8901-4234-5678-90123456D005 | B10: 3F2504E0-4F89-11D3-9A0C-0305E82C3305 | C10: Calle 84 # 51B-20 | D10: Barranquilla | E10: Atlántico | F10: Colombia | G10: 080020 | H10: FALSE
A13: Corresponde a los datos generales del objeto de dominio (nombre, descripción)
A14: Corresponde a las descripciones de los atributos
A15: Coresponde al nombre de los atributos
A16: Corresponde a los datos que son de libre ingreso
A17: Corresponde a los datos que se generarán automáticamente (IdDireccion, idCliente)
A18: Corresponde a la combinación única 1

Sheet C-Direccion
A1: << Ir al modelo de dominio | D1: << Ir al listado de objetos de dominio | G1: << Ir a la caracterización del objeto de dominio
A3: Nombre | B3: ='M-Dirección'!B2
A4: Descripción | B4: ='M-Dirección'!B3
A5: Nombre atributo | B5: Descripción atributo | C5: Identificador del objeto de dominio | D5: Tipo de dato | E5: Obligatorio | F5: Longitud minima(si aplica longitud maxima(si aplica) | G5: Longitud maxima(si aplica longitud maxima(si aplica) | H5: Precisión (si aplica) | I5: Redondeo(si aplica) | J5: Rango inicial(si aplica) | K5: Rango final (si aplica) | L5: Formato(Si aplica) | M5: Reglas especiales(si aplica) | N5: Dato calculado | O5: Aplica ajuste del dato(si aplica) | P5: Carácter de ajuste(si aplica) | Q5: Quitar espacios en blanco al inicio(si aplica) | R5: Quitar espacios en blanco al fin(si aplica) | S5: Dato sensible(si aplica) | T5: Valor por defecto(si aplica) | U5: Auto generado | V5: Registrar una nueva categoría | W5: Consultar la información de las categorías | X5: Permite listar las categorías en la página web para filtrar y buscar productos. | Y5: Actualizar el nombre de una categoría | Z5: Eliminar una categoría
A6: ='M-Dirección'!A5 | B6: ='M-Dirección'!A4 | C6: Si | D6: Alfanumerico | E6: Si | F6: 1 | G6: 20 | L6: Mayusculas | N6: No | O6: No | Q6: Si | R6: Si | S6: No | U6: Si | V6: No requerido | W6: No Requerido | X6: No requerido | Y6: No requerido | Z6: No requerido
A7: ='M-Dirección'!B5 | B7: ='M-Dirección'!B4 | C7: No | D7: <Cliente> | E7: Si | M7: Debe existir un cliente previamente registrado | N7: No | S7: No | U7: No | V7: Requerido | W7: Requerido | X7: Requerido | Y7: Requerido | Z7: Requerido
A8: ='M-Dirección'!C5 | B8: ='M-Dirección'!C4 | C8: No | D8: texto | E8: Si | F8: 4 | G8: 50 | L8: Capitalizado | M8: Solo nombres válidos de divisiones territoriales | N8: No | O8: No | Q8: Si | R8: Si | S8: No | U8: No
A9: ='M-Dirección'!D5 | B9: ='M-Dirección'!D4 | C9: No | D9: texto | E9: Si | F9: 3 | G9: 50 | L9: Capitalizado | M9: Solo nombres válidos de municipios | N9: No | O9: No | Q9: Si | R9: Si | S9: No | U9: No
A10: ='M-Dirección'!E5 | B10: ='M-Dirección'!E4 | C10: No | D10: Alfanumerico | E10: Si | F10: 5 | G10: 150 | M10: Formato de nomenclatura urbana estándar | N10: No | O10: No | Q10: Si | R10: Si | S10: No | U10: No
A11: ='M-Dirección'!F5 | B11: ='M-Dirección'!F4 | C11: No | D11: texto | E11: No | F11: 0 | G11: 200 | M11: Datos complementarios para ubicación | N11: No | O11: No | Q11: Si | R11: Si | S11: No | U11: No
A13: Nombre combinación unica | B13: Descripción | C13: Atributos involucrados
A14: ='M-Dirección'!G5 | B14: ='M-Dirección'!G4 | C14: {='M-Dirección'!E5:F5} | D14: detalleAdicional
A16: Responsabilidad | B16: Descripción | C16: Entradas | F16: Salida | H16: Políticas (Reglas de Negocio) | J16: Excepción
C17: Parámettro | D17: Tipo de dato | E17: Descripci | F17: Tipo de Dato | G17: Descripción | H17: Política | I17: Descripción | J17: Detalle | K17: ¿Qué hago?
A18: ='E-Direccion'!B7 | B18: ='E-Direccion'!C7 | C18: direccionNueva | D18: Dirección | E18: Contiene la información de la nueva dirección a registrar. | F18: Logico | G18: Retorna verdadero si la dirección se agregó correctamente al perfil del cliente. | H18: ='E-Direccion'!G7 | I18: ='E-Direccion'!H7 | J18: Generar excepción indicando qué campo de la dirección no cumple con el formato o es obligatorio. | K18: Detener operación
H19: ='E-Direccion'!G8 | I19: ='E-Direccion'!H8 | J19: Generar excepción indicando que el cliente asociado a la dirección no existe en la base de datos. | K19: Detener operación
A21: ='E-Direccion'!B9 | B21: ='E-Direccion'!C9 | C21: direccionModificada | D21: Dirección | E21: Contiene la nueva información de la ubicación a actualizar. | F21: Logico | G21: Retorna verdadero si la dirección se modificó exitosamente. | H21: ='E-Direccion'!G9 | I21: ='E-Direccion'!H9 | J21: Generar excepción indicando que la dirección no existe o el usuario no tiene permisos para editarla. | K21: Detener operación
A22: ='E-Direccion'!B10 | B22: ='E-Direccion'!C10 | C22: idDireccion | D22: alfanumerico | E22: Identificador exacto de la ubicación que el usuario desea borrar. | F22: Logico | G22: Retorna verdadero si la dirección fue eliminada o inactivada correctamente. | H22: ='E-Direccion'!G10 | I22: ='E-Direccion'!H10 | J22: Generar excepción indicando que la dirección a borrar no existe o no es de su propiedad. | K22: Detener operación
H23: ='E-Direccion'!G11 | I23: ='E-Direccion'!H11 | J23: Generar excepción indicando que la dirección está bloqueada temporalmente porque tiene un envío en curso. | K23: Detener operación
A24: ='E-Direccion'!B12 | B24: ='E-Direccion'!C10 | C24: idCliente | D24: alfanumerico | E24: Identificador del cliente del cual se quieren obtener las ubicaciones guardadas. | F24: Lista<Dirección> | G24: Retorna una colección con los objetos de las direcciones encontradas. | H24: ='E-Direccion'!G12 | I24: ='E-Direccion'!H12 | J24: Generar excepción indicando acceso denegado por intentar consultar direcciones de otro usuario sin rol de administrador. | K24: Detener operación

Sheet E-Direccion
A1: << Ir al modelo de dominio | D1: << Ir al listado de objetos de dominio | H1: << Ir a la caracterización del objeto de dominio | L1: Ir al muestreo de datos del objeto de dominio >>
A2: Objeto de Dominio: | B2: =ListadoObjetosDominio!B5
A3: Descripción: | B3: =ListadoObjetosDominio!C5
A4: Actor | B4: Action/Command | D4: Entity/Aggregate/Object domain | E4: Read Model | G4: Business Rule/Policy | I4: External System | J4: Domain Event | K4: Hotspot/questions/Risk
A5: Actor | B5: Acción | C5: Descripción | D5: Objeto de dominio | E5: Información externa | G5: Políticas | I5: Sistema Externo | J5: Evento | K5: Aspectos por solucionar
E6: Información | F6: Descripción | G6: Número | H6: Descripción
A7: =ListadoObjetosDominio!B3 | B7: Agregar dirección | C7: Registrar una nueva ubicación física para la entrega de pedidos o facturación. | D7: =ListadoObjetosDominio!B5 | E7: idCliente, departamento, ciudad, calle, detalleAdicional Detalle de productos | F7: Formulario de creación con los datos de ubicación vinculados al perfil del usuario. | G7: DIR-POL-01 | H7: Asegurar que los datos requeridos sean válidos a nivel de tipo de dato, formato, longitud y obligatoriedad. | I7: Base de datos | J7: Dirección agregada | K7: Riesgo de que el cliente ingrese una nomenclatura errónea que la transportadora no pueda encontrar
G8: DIR-POL-02 | H8: El idCliente asociado debe existir previamente
A9: =ListadoObjetosDominio!B3 | B9: Modificar dirección | C9: Actualizar los detalles de una dirección existente (ej. corrección de calle o apartamento). | D9: =ListadoObjetosDominio!B5 | E9: idDireccion, departamento, ciudad, calle, detalleAdicional | F9: Formulario pre-poblado con la información actual de la dirección a editar. | G9: DIR-POL-03 | H9: El idDireccion a modificar debe existir y pertenecer al cliente que ejecuta la acción. | I9: Base de datos | J9: Dirección modificada | K9: ¿Qué pasa si el cliente modifica una dirección mientras un pedido en curso ya va en camino hacia la dirección anterior?
A10: Cliente | B10: Eliminar dirección | C10: Quitar una dirección de la libreta de direcciones del usuario para que no aparezca en futuras compras. | D10: =ListadoObjetosDominio!B5 | E10: idDireccion | F10: Identificador de la ubicación que el usuario desea borrar de su perfil. | G10: DIR-POL-04 | H10: El idDireccion a eliminar debe existir y pertenecer al cliente. | I10: Base de datos | J10: Direccion eliminada | K10: Si se elimina físicamente la dirección, se puede dañar el historial de facturas pasadas.
G11: DIR-POL-05 | H11: El sistema no debe permitir eliminar una dirección si está asociada a un pedido en estado "Pendiente" o "En tránsito".
A12: =_xlfn.CONCAT(ListadoObjetosDominio!B3,"/ ",ListadoObjetosDominio!B4,) | B12: Consultar direcciones | C12: Listar las direcciones guardadas de un cliente específico para seleccionarlas en el checkout o dar soporte. | D12: =ListadoObjetosDominio!B5 | E12: idDireccion, departamento, ciudad, calle, detalleAdicional | F12: Vista de libreta de direcciones o panel de selección durante el proceso de compra. | G12: DIR-POL-06 | H12: El cliente solo puede consultar sus propias direcciones; el administrador puede consultar las de cualquier cliente. | I12: Base de datos | J12: Direcciones consultadas | K12: Ninguno identificado en el momento

Sheet M-Categoria
A1: << Ir al modelo de dominio | E1: << Ir al listado de objetos de dominio | H1: << Ir a la caracterización del objeto de dominio
A2: Nombre: | B2: =ListadoObjetosDominio!B6
A3: Descripción: | B3: =ListadoObjetosDominio!C6
A4: Identificador único universal (UUID) de la categoría. | B4: Nombre comercial de la categoría de productos. | C4: Descripción breve de la categoría (opcional). | D4: Indica si la categoría está activa (true) o inactiva (false).
A5: id | B5: nombre | C5: descripcion | D5: estado
A6: CA111111-1111-4111-8111-111111111101 | B6: Hogar | C6: Productos decorativos y utilitarios para el hogar. | D6: TRUE
A7: CA111111-1111-4111-8111-111111111102 | B7: Moda | C7: Prendas de vestir y accesorios de moda. | D7: TRUE
A8: CA111111-1111-4111-8111-111111111103 | B8: Accesorios | C8: Accesorios personales y complementos. | D8: TRUE
A9: CA111111-1111-4111-8111-111111111104 | B9: Tecnología | C9: Dispositivos y accesorios tecnológicos. | D9: TRUE
A10: CA111111-1111-4111-8111-111111111105 | B10: Cocina | C10: Utensilios y menaje de cocina. | D10: FALSE
A12: Corresponde a los datos generales del objeto de dominio (nombre, descripción)
A13: Corresponde a las descripciones de los atributos
A14: Coresponde al nombre de los atributos
A15: Corresponde a los datos que son de libre ingreso (referencia, nombre, descripcion, precio y estado)
A16: Corresponde a los datos que se generarán automáticamente (idCategoria)
A17: Corresponde a la combinación única 1

Sheet C-Categoria
A1: << Ir al modelo de dominio | D1: << Ir al listado de objetos de dominio | G1: << Ir a la caracterización del objeto de dominio
A3: Nombre | B3: ='M-Categoria'!B2
A4: Descripción | B4: ='M-Categoria'!B3
A5: Nombre atributo | B5: Descripción atributo | C5: Identificador del objeto de dominio | D5: Tipo de dato | E5: Obligatorio | F5: Longitud minima(si aplica longitud maxima(si aplica) | G5: Longitud maxima(si aplica longitud maxima(si aplica) | H5: Precisión (si aplica) | I5: Redondeo(si aplica) | J5: Rango inicial(si aplica) | K5: Rango final (si aplica) | L5: Formato(Si aplica) | M5: Reglas especiales(si aplica) | N5: Dato calculado | O5: Aplica ajuste del dato(si aplica) | P5: Carácter de ajuste(si aplica) | Q5: Quitar espacios en blanco al inicio(si aplica) | R5: Quitar espacios en blanco al fin(si aplica) | S5: Dato sensible(si aplica) | T5: Valor por defecto(si aplica) | U5: Auto generado | V5: Registrar una nueva categoría | W5: Consultar la información de las categorías | X5: Permite listar las categorías en la página web para filtrar y buscar productos. | Y5: Actualizar el nombre de una categoría | Z5: Eliminar una categoría
A6: ='M-Categoria'!A5 | B6: ='M-Categoria'!A4 | C6: Si | D6: Alfanumerico | E6: Si | F6: 3 | G6: 20 | L6: Mayusculas | N6: No | O6: No | Q6: Si | R6: Si | S6: No | U6: Si | V6: No requerido | W6: No Requerido | X6: No requerido | Y6: No requerido | Z6: No requerido
A7: ='M-Categoria'!B5 | B7: ='M-Categoria'!B4 | C7: No | D7: Alfanumerico | E7: Si | F7: 3 | G7: 50 | L7: Capitalizado | M7: Nombre comercial de la categoría | N7: No | O7: No | Q7: Si | R7: Si | S7: No | T7: Activo | U7: No | V7: Requerido | W7: Requerido | X7: Requerido | Y7: Requerido | Z7: Requerido
A8: ='M-Categoria'!C5 | B8: ='M-Categoria'!C4 | C8: No | D8: Texto | E8: Si | F8: 5 | G8: 15 | L8: Primera Mayuscula | M8: Solo permite valores 'Activo' o 'Inactivo' | N8: No | O8: No | Q8: Si | R8: Si | S8: No | T8: Activo | U8: No
A10: Nombre combinación unica | B10: Descripción | C10: Atributos involucrados
A11: ='M-Categoria'!D5 | B11: ='M-Categoria'!D4 | C11: ='M-Categoria'!B5
A13: Responsabilidad | B13: Descripción | C13: Entradas | F13: Salida | H13: Políticas (Reglas de Negocio) | J13: Excepción
C14: Parámettro | D14: Tipo de dato | E14: Descripci | F14: Tipo de Dato | G14: Descripción | H14: Política | I14: Descripción | J14: Detalle | K14: ¿Qué hago?
A15: ='E-Categoria'!B7 | B15: ='E-Categoria'!C7 | C15: categoriaNueva | D15: Categoría | E15: Contiene la información de la nueva categoría a registrar. | F15: Logico | G15: Retorna verdadero si la categoría se agregó correctamente al sistema. | H15: ='E-Categoria'!G7 | I15: ='E-Categoria'!H7 | J15: Generar excepción indicando qué campo no cumple con el formato o es obligatorio. | K15: Detener operación
H16: ='E-Categoria'!G8 | I16: ='E-Categoria'!H8 | J16: Generar excepción indicando que ya existe otra categoría registrada con ese mismo nombre. | K16: Detener operación
A17: ='E-Categoria'!B9 | B17: ='E-Categoria'!C9 | C17: ategoriaModificada | D17: Categoría | E17: Contiene la nueva información de la categoría a actualizar. | F17: Logico | G17: Retorna verdadero si la categoría se modificó exitosamente. | H17: ='E-Categoria'!G9 | I17: ='E-Categoria'!H9 | J17: Generar excepción indicando que la categoría que se intenta modificar no existe en la base de datos. | K17: Detener operación
A18: ='E-Categoria'!B10 | B18: ='E-Categoria'!C10 | C18: idCategoria | D18: alfanumerico | E18: Identificador exacto de la categoría que se desea borrar. | F18: Logico | G18: Retorna verdadero si la categoría fue eliminada correctamente. | H18: ='E-Categoria'!G10 | I18: ='E-Categoria'!H10 | J18: Generar excepción indicando que la categoría a borrar no se encuentra registrada. | K18: Detener operación
H19: ='E-Categoria'!G11 | I19: ='E-Categoria'!H11 | J19: Generar excepción indicando que la categoría está en uso por productos existentes y no puede ser eliminada. | K19: Detener operación
A20: ='E-Categoria'!B12 | B20: ='E-Categoria'!C12 | C20: filtros | D20: Texto | E20: Parámetros opcionales para filtrar la búsqueda de categorías. | F20: Lista<Categoría> | G20: Retorna una colección con los objetos de las categorías encontradas. | H20: ='E-Categoria'!G12 | I20: ='E-Categoria'!H12 | J20: Generar excepción indicando que los parámetros de búsqueda tienen un formato incorrecto. | K20: Detener operación

Sheet E-Categoria
A1: << Ir al modelo de dominio | D1: << Ir al listado de objetos de dominio | H1: << Ir a la caracterización del objeto de dominio | L1: Ir al muestreo de datos del objeto de dominio >>
A2: Objeto de Dominio: | B2: =ListadoObjetosDominio!B6
A3: Descripción: | B3: =ListadoObjetosDominio!C6
A4: Actor | B4: Action/Command | D4: Entity/Aggregate/Object domain | E4: Read Model | G4: Business Rule/Policy | I4: External System | J4: Domain Event | K4: Hotspot/questions/Risk
A5: Actor | B5: Acción | C5: Descripción | D5: Objeto de dominio | E5: Información externa | G5: Políticas | I5: Sistema Externo | J5: Evento | K5: Aspectos por solucionar
E6: Información | F6: Descripción | G6: Número | H6: Descripción
A7: Administrador | B7: Crear Categoria | C7: Permite ingresar al sistema una nueva categoría para agrupar los productos del catálogo. | D7: =ListadoObjetosDominio!B6 | E7: nombre, descripcion | F7: Formulario para ingresar el nombre y detalles de la nueva familia de productos. | G7: CAT-POL-01 | H7: Asegurar que los datos requeridos sean válidos a nivel de tipo de dato, formato, longitud y obligatoriedad. | I7: Base de datos | J7: Categoría creada | K7: Riesgo de crear categorías duplicadas o con nombres muy similares que confundan al cliente.
G8: CAT-POL-02 | H8: El nombre de la categoría debe ser único en el sistema para evitar duplicidad.
A9: Administrador | B9: Modificar categoría | C9: Actualizar los detalles de una categoría existente (ej. corregir ortografía o ampliar la descripción). | D9: =ListadoObjetosDominio!B6 | E9: idCategoria, nombre, descripcion | F9: Formulario pre-poblado con la información actual de la categoría a editar. | G9: CAT-POL-03 | H9: El idCategoria a modificar debe existir previamente en el sistema. | I9: Base de datos | J9: Categoría modificada | K9: Cambiar el nombre drásticamente podría desorientar a los clientes que buscan productos específicos.
A10: Administrador | B10: Eliminar categoría | C10: Quitar una categoría del catálogo para que ya no esté disponible en la tienda. | D10: =ListadoObjetosDominio!B6 | E10: idCategoria | F10: Identificador de la agrupación que el administrador desea retirar. | G10: CAT-POL-04 | H10: El idCategoria a eliminar debe existir previamente en el sistema. | I10: Base de datos | J10: Categoría eliminada | K10: Riesgo crítico: dejar productos "huérfanos". ¿Qué pasa con los productos si se borra su categoría?
G11: CAT-POL-05 | H11: El sistema debe impedir la eliminación de la categoría si esta tiene uno o más productos asociados actualmente.
A12: Cliente / Administrador | B12: Consultar categorías | C12: Listar las categorías disponibles para desplegarlas en el menú de navegación o panel administrativo. | D12: Categoría | E12: idCategoria, nombre, descripcion | F12: Menú visual en la tienda web o grilla en el panel de control del administrador. | G12: CAT-POL-06 | H12: Asegurar que los datos requeridos sean válidos a nivel de tipo de dato, formato, longitud y obligatoriedad. | I12: Base de datos | J12: Categorías consultadas | K12: Si hay demasiadas categorías cargadas al mismo tiempo, el menú principal podría volverse inmanejable.

Sheet M-Producto
A1: << Ir al modelo de dominio | D1: << Ir al listado de objetos de dominio | G1: << Ir a la caracterización del objeto de dominio
A2: Nombre | B2: =ListadoObjetosDominio!B7
A3: Descripción | B3: =ListadoObjetosDominio!C7
A4: Identificador único universal (UUID) del producto. | B4: Referencia a la categoría a la que pertenece el producto. | C4: Nombre comercial del producto. | D4: Descripción detallada de las características del producto. | E4: Precio del producto en pesos colombianos (COP). | F4: Cantidad de unidades disponibles en inventario. | G4: Ruta relativa a la imagen representativa del producto (opcional). | H4: Indica si el producto está activo (true) o inactivo (false).
A5: id | B5: categoria | C5: nombre | D5: descripcion | E5: precio | F5: stock | G5: imagenUrl | H5: estado
A6: 4F8A0001-2222-4333-8444-555566667701 | B6: CA111111-1111-4111-8111-111111111101 | C6: Lámpara decorativa NP5115 | D6: Lámpara de mesa decorativa con base metálica y pantalla en tela. | E6: 89900 | F6: 25 | G6: img/Lampara_NP5115.png | H6: TRUE
A7: 4F8A0001-2222-4333-8444-555566667702 | B7: CA111111-1111-4111-8111-111111111103 | C7: Sombrilla antiviento NP4292 | D7: Sombrilla plegable antiviento con forro reforzado y mango ergonómico. | E7: 145000 | F7: 40 | G7: img/Sombrilla_antiviento_NP4292.png | H7: TRUE
A8: 4F8A0001-2222-4333-8444-555566667703 | B8: CA111111-1111-4111-8111-111111111102 | C8: Gorra para hombre NP5275 | D8: Gorra deportiva para hombre con visera curva y ajuste trasero. | E8: 35500 | F8: 60 | G8: img/Gorra_hombre_NP5275.png | H8: TRUE
A9: 4F8A0001-2222-4333-8444-555566667704 | B9: CA111111-1111-4111-8111-111111111105 | C9: Set de cucharas inoxidables x 12 | D9: Set de 12 cucharas en acero inoxidable con diseño labrado. | E9: 32000 | F9: 0 | H9: FALSE
A10: 4F8A0001-2222-4333-8444-555566667705 | B10: CA111111-1111-4111-8111-111111111104 | C10: Audífonos inalámbricos | D10: Audífonos bluetooth con cancelación de ruido y estuche de carga. | E10: 189900 | F10: 15 | H10: TRUE
A13: Corresponde a los datos generales del objeto de dominio (nombre, descripción)
A14: Corresponde a las descripciones de los atributos
A15: Coresponde al nombre de los atributos
A16: Corresponde a los datos que son de libre ingreso (referencia, nombre, descripcion, precio y estado)
A17: Corresponde a referencias a otros objetos de dominio (idCategoria)
A18: Corresponde a los datos que se generarán automáticamente (idProducto)
A19: Corresponde a la combinación única 1

Sheet C-Producto
A1: << Ir al modelo de dominio | D1: << Ir al listado de objetos de dominio | G1: << Ir a la caracterización del objeto de dominio
A2: Nombre | B2: ='M-Producto'!B2
A3: Descripción | B3: ='M-Producto'!B3
A4: Nombre atributo | B4: Descripción atributo | C4: Identificador del objeto de dominio | D4: Tipo de dato | E4: Obligatorio | F4: Longitud minima(si aplica longitud maxima(si aplica) | G4: Longitud maxima(si aplica longitud maxima(si aplica) | H4: Precisión (si aplica) | I4: Redondeo(si aplica) | J4: Rango inicial(si aplica) | K4: Rango final (si aplica) | L4: Formato(Si aplica) | M4: Reglas especiales(si aplica) | N4: Dato calculado | O4: Aplica ajuste del dato(si aplica) | P4: Carácter de ajuste(si aplica) | Q4: Quitar espacios en blanco al inicio(si aplica) | R4: Quitar espacios en blanco al fin(si aplica) | S4: Dato sensible(si aplica) | T4: Valor por defecto(si aplica) | U4: Auto generado | V4: Registrar un nuevo producto | W4: Consultar la información de los productos | X4: Consultar la información de los productos | Y4: Actualizar la información de un producto | Z4: Eliminar un producto
A5: ='M-Producto'!A5 | B5: ='M-Producto'!A4 | C5: Si | D5: Alfanumerico | E5: Si | F5: 1 | G5: 20 | L5: Mayusculas | N5: No | O5: No | Q5: Si | R5: Si | S5: No | U5: Si | V5: No requerido | W5: No requerido | X5: No requerido | Y5: Requerido | Z5: Requerido
A6: ='M-Producto'!B5 | B6: ='M-Producto'!B4 | C6: No | D6: <Categoria> | E6: Si | F6: 1 | G6: 50 | M6: Debe corresponder a una categoría válida del catálogo | N6: No | O6: No | S6: No | U6: No | V6: Requerido | W6: No requerido | X6: No requerido | Y6: Requerido | Z6: No requerido
A7: ='M-Producto'!C5 | B7: ='M-Producto'!C4 | C7: No | D7: Alfanumerico | E7: Si | F7: 1 | G7: 100 | L7: Mayusculas | M7: Debe corresponder a una categoría válida del catálogo | N7: No | O7: No | Q7: Si | R7: Si | S7: No | U7: No | V7: Requerido | W7: No requerido | X7: No requerido | Y7: Requerido | Z7: No requerido
A8: ='M-Producto'!D5 | B8: ='M-Producto'!D4 | C8: No | D8: Texto | E8: Si | F8: 5 | G8: 100 | L8: Capitalizado | N8: No | O8: No | Q8: Si | R8: Si | S8: No | U8: No | V8: Requerido | W8: No requerido | X8: No requerido | Y8: Requerido | Z8: No requerido
A9: ='M-Producto'!E5 | B9: ='M-Producto'!E4 | C9: No | D9: Numerico decimal | E9: Si | H9: 2 | I9: Truncamiento | J9: 1 | K9: 99999999 | M9: El valor no puede ser menor o igual a cero | N9: No | S9: No | U9: No | V9: No requerido | W9: No requerido | X9: No requerido | Y9: No requerido | Z9: No requerido
A10: ='M-Producto'!F5 | B10: ='M-Producto'!F4 | C10: No | D10: Texto | E10: No | F10: 0 | G10: 500 | N10: No | O10: No | Q10: Si | R10: Si | S10: No | U10: No | V10: No requerido | W10: No requerido | X10: No requerido | Y10: Requerido | Z10: No requerido
A11: ='M-Producto'!G5 | B11: ='M-Producto'!G4 | C11: No | D11: Texto | E11: Si | F11: 5 | G11: 15 | L11: Capitalizado | M11: Solo permite los valores 'Activo' o 'Inactivo' | N11: No | O11: No | Q11: No | R11: Si | S11: No | T11: Activo | U11: No | V11: Requerido | W11: No requerido | X11: No requerido | Y11: Requerido | Z11: No requerido
A13: Nombre combinación unica | B13: Descripción | C13: Atributos involucrados
A14: ='M-Producto'!H5 | B14: ='M-Producto'!H4 | C14: ='M-Producto'!C5
A16: Responsabilidad | B16: Descripción | C16: Entradas | F16: Salida | H16: Políticas (Reglas de Negocio) | J16: Excepción
C17: Parámettro | D17: Tipo de dato | E17: Descripci | F17: Tipo de Dato | G17: Descripción | H17: Política | I17: Descripción | J17: Detalle | K17: ¿Qué hago?
A18: ='E-Producto'!B7 | B18: ='E-Producto'!C7 | C18: productoNuevo | D18: Producto | E18: Contiene la información del producto que se va a registrar. | F18: Logico | G18: Retorna verdadero si el producto se agregó correctamente. | H18: ='E-Producto'!G7 | I18: ='E-Producto'!H7 | J18: Generar excepción indicando qué campo no cumple con el formato o es obligatorio. | K18: Detener operación
H19: ='E-Producto'!G8 | I19: ='E-Producto'!H8 | J19: Generar excepción indicando que la categoría asignada al producto no existe. | K19: Detener operación
H20: ='E-Producto'!G9 | I20: ='E-Producto'!H9 | J20: Generar excepción indicando que el SKU ya está en uso por otro producto. | K20: Detener operación
A21: ='E-Categoria'!B12 | B21: ='E-Categoria'!C12 | C21: productoModificado | D21: Producto | E21: Contiene la nueva información del producto a actualizar. | F21: Logico | G21: Retorna verdadero si el producto se modificó exitosamente. | H21: ='E-Producto'!G10 | I21: ='E-Producto'!H10 | J21: Generar excepción indicando que el producto a modificar no existe en la base de datos. | K21: Detener operación
H22: ='E-Producto'!G11 | I22: ='E-Producto'!H11 | J22: Generar excepción indicando que el nuevo SKU ingresado ya pertenece a otro producto. | K22: Detener operación
A23: ='E-Producto'!B12 | B23: ='E-Producto'!C12 | C23: idProducto | D23: alfanumerico | E23: Identificador exacto del producto que se desea borrar o inactivar. | F23: Logico | G23: Retorna verdadero si el producto fue eliminado o desactivado correctamente. | H23: ='E-Producto'!G12 | I23: ='E-Producto'!H12 | J23: Generar excepción indicando que el producto a eliminar no se encuentra registrado. | K23: Detener operación
H24: ='E-Producto'!G13 | I24: ='E-Producto'!H13 | J24: Generar excepción indicando que el producto tiene historial de ventas y solo puede ser inactivado. | K24: Detener operación
A25: ='E-Producto'!A14 | B25: ='E-Producto'!C14 | C25: filtros | D25: Texto | E25: Parámetros opcionales para filtrar la búsqueda de productos. | F25: Lista<Producto> | G25: Retorna una colección con los objetos de los productos encontrados. | H25: ='E-Producto'!G14 | I25: ='E-Producto'!H14 | J25: Generar excepción indicando acceso denegado por intentar consultar productos inactivos sin permisos administrativos. | K25: Detener operación

Sheet E-Producto
A1: << Ir al modelo de dominio | E1: << Ir al listado de objetos de dominio | I1: << Ir a la caracterización del objeto de dominio
A2: Objeto de Dominio: | B2: =ListadoObjetosDominio!B7
A3: Descripción: | B3: =ListadoObjetosDominio!C7
A4: Actor | B4: Action/Command | D4: Entity/Aggregate/Object domain | E4: Read Model | G4: Business Rule/Policy | I4: External System | J4: Domain Event | K4: Hotspot/questions/Risk
A5: Actor | B5: Acción | C5: Descripción | D5: Objeto de dominio | E5: Información externa | G5: Políticas | I5: Sistema Externo | J5: Evento | K5: Aspectos por solucionar
E6: Información | F6: Descripción | G6: Número | H6: Descripción
A7: Administrador | B7: Registrar un nuevo producto | C7: Añadir un nuevo artículo (ej. un portátil) al catálogo de ventas asociándolo a una categoría. | D7: =ListadoObjetosDominio!B7 | E7: idcategoria, referencia(SKU), nombre, precio, descripcion, estado | F7: Formulario para ingresar las características, valor y cantidad inicial del artículo. | G7: PRO-POL-01 | H7: Asegurar que los datos requeridos sean válidos a nivel de tipo, formato, rango y obligatoriedad. | I7: Base de datos | J7: Producto registrado | K7: ¿Qué pasa si se registra un producto sin imagen? ¿El sistema debe asignar una imagen "por defecto" (placeholder)?
G8: PRO-POL-02 | H8: El idCategoria asociado debe existir previamente en el sistema.
G9: PRO-POL-03 | H9: La referencia(SKU) no debe existir previamente en el sistema (Combinación única).
A10: Administrador | B10: Modificar producto | C10: Actualizar la información de un producto, como cambiar su precio o ajustar el inventario manualmente. | D10: =ListadoObjetosDominio!B7 | E10: idProducto, idcategoria, referencia(SKU), nombre, precio, descripcion, estado | F10: Formulario pre-poblado con los datos actuales del producto para ser editados. | G10: PRO-POL-04 | H10: El idProducto proporcionado debe existir obligatoriamente en el catálogo. | I10: Base de datos | J10: Producto modificado | K10: Si se cambia el precio de un producto, ¿esto afecta automáticamente a los carritos de compras que los clientes aún no han pagado?
G11: PRO-POL-05 | H11: Si se modifica la referencia(SKU), la nueva no debe colisionar con otra existente.
A12: Administrador | B12: Eliminar producto | C12: Retirar un producto del catálogo para que no pueda ser visualizado ni comprado por los clientes. | D12: =ListadoObjetosDominio!B7 | E12: idProducto | F12: Identificador del producto que el administrador desea eliminar. | G12: PRO-POL-06 | H12: El idProducto a eliminar debe existir previamente en el sistema. | I12: Base de datos | J12: Producto eliminado | K12: Afectación en el SEO de la página web si se desactiva masivamente la URL de productos muy visitados.
G13: PRO-POL-07 | H13: El sistema no debe permitir eliminar el producto si este ya se encuentra asociado a un pedido histórico (se recomienda desactivarlo).
A14: Cliente/Administrador | B14: Consultar productos | C14: Listar y visualizar los detalles de los productos disponibles en la tienda web o panel de control. | D14: =ListadoObjetosDominio!B7 | E14: idProducto, idcategoria, referencia(SKU), nombre, precio, estado | F14: Vitrina virtual (Storefront) para el cliente o tabla de gestión para el administrador. | G14: PRO-POL-08 | H14: El Cliente solo puede ver productos en estado "Activo"; el Administrador puede ver todos los estados. | I14: Base de datos | J14: Productos consultados | K14: Si hay miles de productos, la consulta puede volver lento el sistema (se requiere paginación).

Sheet M-ImagenProducto
A1: << Ir al modelo de dominio | D1: << Ir al listado de objetos de dominio | G1: << Ir a la caracterización del objeto de dominio
A3: Nombre | B3: =ListadoObjetosDominio!B8
A4: Descripción | B4: =ListadoObjetosDominio!C8
A5: Representa el identificador único de cada imagen generado automáticamente por el sistema. | B5: Representa el objeto de dominio Producto al cual pertenece esta imagen. | C5: Representa la ruta web o enlace donde está alojada la fotografía del artículo | D5: Representa el número secuencial que define en qué orden se muestran las fotos en la galería | E5: Indica que no pueden existir dos imágenes con la misma URL asociadas al mismo producto.
A6: idimagen | B6: idproducto | C6: foto | D6: ordenVisualizacion | E6: Combinación única 1
A7: IMG-001 | B7: ='M-Producto'!A6 | C7: /assets/sombrilla-antiviento-1.jpg | D7: 1 | E7: =_xlfn.CONCAT(B7,"-",D7)
A8: IMG-002 | B8: ='M-Producto'!A6 | C8: /assets/sombrilla-antiviento-abierta.jpg | D8: 2 | E8: =_xlfn.CONCAT(B8,"-",D8)
A9: IMG-003 | B9: ='M-Producto'!A7 | C9: /assets/gorra-ninos-azul.jpg | D9: 1 | E9: =_xlfn.CONCAT(B9,"-",D9)
A10: IMG-004 | B10: P-0002 | C10: /assets/gorra-ninos-beige.jpg | D10: 2 | E10: =_xlfn.CONCAT(B10,"-",D10)
A11: IMG-005 | B11: ='M-Producto'!A8 | C11: /assets/tapete-bienvenido-verde.jpg | D11: 1 | E11: =_xlfn.CONCAT(B11,"-",D11)
A14: Corresponde a los datos generales del objeto de dominio (nombre, descripción)
A15: Corresponde a las descripciones de los atributos
A16: Coresponde al nombre de los atributos
A17: Corresponde a los datos que son de libre ingreso
A18: Corresponde a los datos que se generarán automáticamente
A19: Corresponde a la combinación única 1
A20: Corresponde a referencias a otros objetos de dominio

Sheet C-ImagenProducto 
A1: << Ir al modelo de dominio | D1: << Ir al listado de objetos de dominio | G1: << Ir a la caracterización del objeto de dominio
A2: Nombre | B2: ='M-ImagenProducto'!B3
A3: Descripción | B3: ='M-ImagenProducto'!B4
A4: Nombre atributo | B4: Descripción atributo | C4: Identificador del objeto de dominio | D4: Tipo de dato | E4: Obligatorio | F4: Longitud minima(si aplica longitud maxima(si aplica) | G4: Longitud maxima(si aplica longitud maxima(si aplica) | H4: Precisión (si aplica) | I4: Redondeo(si aplica) | J4: Rango inicial(si aplica) | K4: Rango final (si aplica) | L4: Formato(Si aplica) | M4: Reglas especiales(si aplica) | N4: Dato calculado | O4: Aplica ajuste del dato(si aplica) | P4: Carácter de ajuste(si aplica) | Q4: Quitar espacios en blanco al inicio(si aplica) | R4: Quitar espacios en blanco al fin(si aplica) | S4: Dato sensible(si aplica) | T4: Valor por defecto(si aplica) | U4: Auto generado | V4: =#REF! | W4: =#REF! | X4: =#REF! | Y4: =#REF!
A5: ='M-ImagenProducto'!A6 | B5: ='M-ImagenProducto'!A5 | C5: Si | D5: Alfanumerico | E5: Si | F5: 1 | G5: 20 | N5: No | O5: No | Q5: Si | R5: Si | S5: No | U5: Si | V5: Requerido | W5: No requerido
A6: ='M-ImagenProducto'!B6 | B6: ='M-ImagenProducto'!B5 | C6: No | D6: <Producto> | E6: Si | M6: Debe corresponder a un producto existente en el catálogo | N6: No | S6: No | U6: No | V6: No requerido | W6: No requerido
A7: ='M-ImagenProducto'!C6 | B7: ='M-ImagenProducto'!C5 | C7: No | D7: Texto | E7: Si | F7: 5 | G7: 500 | L7: URL / Minúsculas | M7: Debe ser una ruta válida terminada en extensión de imagen (ej. .jpg, .png, .webp) | N7: No | O7: No | Q7: Si | R7: Si | S7: No | U7: No | V7: Norequerido | W7: No requerido
A8: ='M-ImagenProducto'!D6 | B8: ='M-ImagenProducto'!D5 | C8: No | D8: Numerico entero | E8: Si | J8: 1 | K8: 20 | M8: Determina la posición de la foto en la galería del producto (1 es la foto principal) | N8: No | S8: No | T8: 1 | U8: No
A10: Nombre combinación unica | B10: Descripción | C10: Atributos involucrados
A11: ='M-ImagenProducto'!E6 | B11: ='M-ImagenProducto'!E5 | C11: ='M-ImagenProducto'!B6
C12: ='M-ImagenProducto'!D6
A14: Responsabilidad | B14: Descripción | C14: Entradas | F14: Salida | H14: Políticas (Reglas de Negocio) | J14: Excepción
C15: Parámettro | D15: Tipo de dato | E15: Descripci | F15: Tipo de Dato | G15: Descripción | H15: Política | I15: Descripción | J15: Detalle | K15: ¿Qué hago?
A16: ='E-ImagenProducto'!B7 | B16: ='E-ImagenProducto'!C7 | C16: magenNueva | D16: ImagenProducto | E16: Contiene la información y el archivo de la nueva imagen a registrar. | F16: Logico | G16: Retorna verdadero si la imagen se agregó correctamente al producto. | H16: ='E-ImagenProducto'!G7 | I16: ='E-ImagenProducto'!H7 | J16: Generar excepción indicando qué campo no cumple con el formato o es obligatorio. | K16: Detener operación
H17: P2 | I17: El idProducto asociado debe existir previamente en el sistema. | J17: Generar excepción indicando que el producto asociado no existe. | K17: Detener operación
H18: ='E-ImagenProducto'!G9 | I18: ='E-ImagenProducto'!H9 | J18: Generar excepción indicando que el formato del archivo subido no es permitido. | K18: Detener operación
A19: ='E-ImagenProducto'!B10 | B19: ='E-ImagenProducto'!F10 | C19: imagenModificada | D19: ImagenProducto | E19: Contiene la nueva información de la imagen y su orden de visualización. | F19: Logico | G19: Retorna verdadero si la imagen o su orden se modificó exitosamente. | H19: ='E-ImagenProducto'!G10 | I19: ='E-ImagenProducto'!H10 | J19: Generar excepción indicando que la imagen a modificar no existe en la base de datos. | K19: Detener operación
H20: ='E-ImagenProducto'!G11 | I20: ='E-ImagenProducto'!H11 | J20: Generar excepción indicando que el orden de visualización ya está ocupado por otra imagen. | K20: Detener operación
A21: ='E-ImagenProducto'!B12 | B21: ='E-ImagenProducto'!C12 | C21: idImagen | D21: alfanumerico | E21: Identificador exacto de la imagen que se desea borrar. | F21: Logico | G21: Retorna verdadero si la imagen fue eliminada correctamente. | H21: ='E-ImagenProducto'!G12 | I21: ='E-ImagenProducto'!H12 | J21: Generar excepción indicando que la imagen a eliminar no se encuentra registrada. | K21: Detener operación
H22: ='E-ImagenProducto'!G13 | I22: ='E-ImagenProducto'!H13 | J22: Generar excepción indicando que no se puede eliminar porque el producto debe conservar al menos una imagen. | K22: Detener operación
