Workbook

Sheet Modelo de dominio
A1: Ir al listado de objetos de dominio >>

Sheet Modelo de dominio anémico
A1: Ir al listado de objetos de dominio >>

Sheet ListadoObjetosDominio
A1: <<Ir al modelo de dominio
A2: Línea de vida | B2: Nombre | C2: Descripción | D2: Muestreo de datos | E2: Caracterización objeto | F2: Event Storming | G2: Politicas
A3: 1 | B3: Cliente | C3: Objeto de dominio que representa a cada uno de los usuarios registrados que realizan compras en la plataforma de Imexcol. | D3: Ir | E3: =HYPERLINK("#'C-Cliente'!B2", "Ir") -> Ir | F3: Ir | G3: Ir
A4: 2 | B4: Administrador | C4: Objeto de dominio que representa al personal interno encargado de gestionar el catálogo, los pedidos y la operación general del sistema. | D4: Ir | E4: =HYPERLINK("#'C-Administrador'!B2", "Ir") -> Ir | F4: Ir | G4: Ir
A5: 3 | B5: Dirección | C5: Objeto de dominio que representa la ubicación física y estructurada que registra un cliente para la entrega de sus productos o propósitos de facturación. | D5: Ir | E5: =HYPERLINK("#'C-Direccion'!B2", "Ir") -> Ir | F5: Ir | G5: Ir
A6: 4 | B6: Categoría | C6: Objeto de dominio que representa a cada una de las agrupaciones taxonómicas en las que se organizan los productos del catálogo de Imexcol. | D6: Ir | E6: =HYPERLINK("#'C-Categoria'!B2", "Ir") -> Ir | F6: Ir | G6: Ir
A7: 5 | B7: Producto | C7: Objeto de dominio que representa a cada uno de los artículos de importación (bolsos, juguetes, etc.) que están disponibles para la venta en la tienda. | D7: Ir | E7: =HYPERLINK("#'C-Producto'!B2", "Ir") -> Ir | F7: Ir | G7: Ir
A8: 6 | B8: ImagenProducto | C8: Objeto de dominio que representa a cada uno de los recursos visuales o fotografías asociadas a un producto para su exhibición. | D8: Ir | E8: =HYPERLINK("#'C-ImagenProducto'!B2", "Ir") -> Ir | F8: Ir | G8: Ir
A9: 7 | B9: Reseña | C9: Objeto de dominio que representa a cada una de las calificaciones y comentarios dejados por un cliente sobre un producto específico que ya ha comprado. | D9: Ir | E9: =HYPERLINK("#'C-Reseña'!B2", "Ir") -> Ir | F9: Ir | G9: Ir
A10: 8 | B10: CarritoCompras | C10: Objeto de dominio que representa la sesión temporal donde un cliente agrupa los productos que tiene intención de adquirir antes de formalizar la transacción. | D10: Ir | E10: =HYPERLINK("#'C-CarritoCompras'!B2", "Ir") -> Ir | F10: Ir | G10: Ir
A11: 9 | B11: ItemCarrito | C11: Objeto de dominio que representa a cada una de las selecciones individuales (producto específico y cantidad) dentro del carrito activo de un cliente. | D11: Ir | E11: =HYPERLINK("#'C-ItemCarrito'!B2", "Ir") -> Ir | F11: Ir | G11: Ir
A12: 10 | B12: Pedido | C12: Objeto de dominio que representa la confirmación formal, transaccional y definitiva de una compra realizada por un cliente en Imexcol. | D12: Ir | E12: =HYPERLINK("#'C-Pedido'!B2", "Ir") -> Ir | F12: Ir | G12: Ir
A13: 11 | B13: LineaPedido | C13: Objeto de dominio que representa el detalle individual de un pedido, permitiendo registrar de forma histórica cada producto adquirido, su cantidad y su valor al momento de confirmar la compra. (Evidencia histórica de la compra) | D13: Ir | E13: =HYPERLINK("#'C-LineaPedido'!B2", "Ir") -> Ir | F13: Ir | G13: Ir
A14: 12 | B14: Pago | C14: Objeto de dominio que representa el registro de la transacción financiera procesada a través de la pasarela de pagos para saldar un pedido. | D14: Ir | E14: =HYPERLINK("#'C-Pago'!B2", "Ir") -> Ir | F14: Ir | G14: Ir
A15: 13 | B15: MetodoPago | C15: Objeto de dominio que representa el instrumento financiero o forma transaccional utilizada por el cliente (tarjeta de crédito, PSE, etc.) para realizar el pago. | D15: Ir | E15: =HYPERLINK("#'C-MetodoPago'!B2", "Ir") -> Ir | F15: Ir | G15: Ir
A16: 14 | B16: Factura | C16: Objeto de dominio que representa el comprobante legal y contable emitido al cliente con el desglose de impuestos una vez el pago ha sido exitoso. | D16: Ir | E16: =HYPERLINK("#'C-Factura'!B2", "Ir") -> Ir | F16: Ir | G16: Ir
A17: 15 | B17: Envio | C17: Objeto de dominio que representa el proceso logístico y de despacho de un pedido aprobado hacia la dirección de entrega del cliente. | D17: Ir | E17: =HYPERLINK("#'C-Envio'!B2", "Ir") -> Ir | F17: Ir | G17: Ir
A18: 16 | B18: EventoRastreo | C18: Objeto de dominio que representa a cada una de las actualizaciones o hitos temporales (ej. en preparación, en tránsito, entregado) que ocurren durante el ciclo de vida de un envío. | D18: Ir | E18: =HYPERLINK("#'C-EnvioRastreo'!B2", "Ir") -> Ir | F18: Ir | G18: Ir

Sheet M-Cliente
A1: << Ir al modelo de dominio | I1: << Ir a la caracterización del objeto de dominio
F2: << Ir al listado de objetos de dominio
A3: Nombre | B3: =ListadoObjetosDominio!B3 -> Cliente
A4: Descripción | B4: =ListadoObjetosDominio!C3 -> Objeto de dominio que representa a cada uno de los usuarios registrados que realizan compras en la plataforma de Imexcol.
A5: Representa el identificador único de cada cliente, generado automáticamente por el sistema. | B5: Representa el tipo de documento de identidad del usuario | C5: Número oficial del documento de identidad | D5: Representa el nombre completo del cliente | E5: Representa el correo electrónico principal de contacto del cliente. | F5: Representa el número de teléfono celular de contacto del cliente. | G5: Indica que no pueden existir dos clientes o más con el mismo correo electrónico. | H5: Indica que no pueden existir dos clientes con el mismo id
A6: id | B6: nombre | C6: apellido | D6: correoElectronico | E6: contrasena | F6: telefono | G6: Combinación única 1 | H6: Combinación única 2
A7: 3F2504E0-4F89-11D3-9A0C-0305E82C3301 | B7: Carlos | C7: Restrepo | D7: carlos.restrepo@imexcol.com | E7: ******** | F7: 3001112233 | G7: =D7 -> carlos.restrepo@imexcol.com | H7: =A7 -> 3F2504E0-4F89-11D3-9A0C-0305E82C3301
A8: 3F2504E0-4F89-11D3-9A0C-0305E82C3302 | B8: María | C8: González | D8: maria.gonzalez@imexcol.com | E8: ******** | F8: 3104445566 | G8: =D8 -> maria.gonzalez@imexcol.com | H8: =A8 -> 3F2504E0-4F89-11D3-9A0C-0305E82C3302
A9: 3F2504E0-4F89-11D3-9A0C-0305E82C3303 | B9: Andrés | C9: Mejía | D9: andres.mejia@imexcol.com | E9: ******** | F9: 3207778899 | G9: =D9 -> andres.mejia@imexcol.com | H9: =A9 -> 3F2504E0-4F89-11D3-9A0C-0305E82C3303
A10: 3F2504E0-4F89-11D3-9A0C-0305E82C3304 | B10: Camila | C10: Ramírez | D10: camila.ramirez@imexcol.com | E10: ******** | F10: 3151231234 | G10: =D10 -> camila.ramirez@imexcol.com | H10: =A10 -> 3F2504E0-4F89-11D3-9A0C-0305E82C3304
A11: 3F2504E0-4F89-11D3-9A0C-0305E82C3305 | B11: Daniel | C11: Pérez | D11: daniel.perez@imexcol.com | E11: ******** | F11: 3009998877 | G11: =D11 -> daniel.perez@imexcol.com | H11: =A11 -> 3F2504E0-4F89-11D3-9A0C-0305E82C3305
A14: Corresponde a los datos generales del objeto de dominio (nombre, descripción)
A15: Corresponde a las descripciones de los atributos
A16: Coresponde al nombre de los atributos
A17: Corresponde a los datos que son de libre ingreso
A18: Corresponde a los datos que se generarán automáticamente (idCliente)
A19: Corresponde a la combinación única 1
A20: Corresponde a la combinación única 2

Sheet C-Cliente
A1: << Ir al modelo de dominio | D1: << Ir al listado de objetos de dominio | G1: << Ir a la caracterización del objeto de dominio
A2: Nombre | B2: ='M-Cliente'!B3 -> Cliente
A3: Descripción | B3: ='M-Cliente'!B4 -> Objeto de dominio que representa a cada uno de los usuarios registrados que realizan compras en la plataforma de Imexcol.
A4: Nombre atributo | B4: Descripción atributo | C4: Identificador del objeto de dominio | D4: Tipo de dato | E4: Obligatorio | F4: Longitud minima(si aplica longitud maxima(si aplica) | G4: Longitud maxima(si aplica longitud maxima(si aplica) | H4: Precisión (si aplica) | I4: Redondeo(si aplica) | J4: Rango inicial(si aplica) | K4: Rango final (si aplica) | L4: Formato(Si aplica) | M4: Reglas especiales(si aplica) | N4: Dato calculado | O4: Aplica ajuste del dato(si aplica) | P4: Carácter de ajuste(si aplica) | Q4: Quitar espacios en blanco al inicio(si aplica) | R4: Quitar espacios en blanco al fin(si aplica) | S4: Dato sensible(si aplica) | T4: Valor por defecto(si aplica) | U4: Auto generado
A5: ='M-Cliente'!A6 -> id | B5: ='M-Cliente'!A5 -> Representa el identificador único de cada cliente, generado automáticamente por el sistema. | C5: Si | D5: Alfanumerico | E5: Si | F5: 1 | L5: Mayusculas | N5: No | O5: No | Q5: Si | R5: Si | S5: No | U5: Si
A6: ='M-Cliente'!B6 -> nombre | B6: ='M-Cliente'!B5 -> Representa el tipo de documento de identidad del usuario | C6: No | D6: Alfanumerico | E6: Si | F6: 2 | G6: 100 | L6: Mayusculas | M6: Solo valores: CC, CE, NIT, TI | N6: No | O6: Si | P6: Espacio | Q6: Si | R6: Si | S6: No | U6: No
A7: ='M-Cliente'!C6 -> apellido | B7: ='M-Cliente'!D5 -> Representa el nombre completo del cliente | C7: No | D7: Alfanumerico | E7: Si | F7: 5 | G7: 100 | M7: Solo caracteres alfanuméricos | N7: No | O7: No | Q7: Si | R7: Si | S7: Si | U7: No
A8: ='M-Cliente'!D6 -> correoElectronico | B8: ='M-Cliente'!D5 -> Representa el nombre completo del cliente | C8: No | D8: Alfanumerico | E8: Si | F8: 3 | G8: 150 | L8: Capitalizado | N8: No | O8: No | Q8: Si | R8: Si | S8: No | U8: No
A9: ='M-Cliente'!E6 -> contrasena | B9: ='M-Cliente'!E5 -> Representa el correo electrónico principal de contacto del cliente. | C9: No | D9: Alfanumerico | E9: Si | F9: 5 | G9: 255 | L9: email | M9: Debe contener '@' y dominio válido | N9: No | O9: No | Q9: Si | R9: Si | S9: Si | U9: No
A10: ='M-Cliente'!F6 -> telefono | B10: ='M-Cliente'!F5 -> Representa el número de teléfono celular de contacto del cliente. | C10: No | D10: Alfanumerico | E10: No | F10: 10 | G10: 20 | N10: No | O10: No | Q10: No | R10: No | S10: Si | U10: No
A12: Nombre combinación unica | B12: Descripción | C12: Atributos involucrados
A13: ='M-Cliente'!G6 -> Combinación única 1 | B13: ='M-Cliente'!G5 -> Indica que no pueden existir dos clientes o más con el mismo correo electrónico. | C13: ='M-Cliente'!D6 -> correoElectronico
A14: ='M-Cliente'!H6 -> Combinación única 2 | B14: ='M-Cliente'!H5 -> Indica que no pueden existir dos clientes con el mismo id | C14: ='M-Cliente'!A6 -> id
A16: Responsabilidad | B16: Descripción | C16: Entradas | F16: Salida | H16: Políticas (Reglas de Negocio) | J16: Excepción
C17: Parámetro | D17: Tipo de dato | E17: Descripción | F17: Tipo de Dato | G17: Descripción | H17: Política | I17: Descripción | J17: Detalle | K17: ¿Qué hago?
A18: ='E-Cliente'!B7 -> Registrar información del cliente | B18: ='E-Cliente'!C7 -> Crear una nueva cuenta de usuario en la plataforma de comercio electrónico de Imexcol para poder realizar compras. | C18: clienteNuevo | D18: Cliente | E18: Contiene la información del cliente que se va a registrar. | F18: Logico | G18: Retorna verdadero si el cliente se registró y guardó correctamente. | H18: ='E-Cliente'!G7 -> CLI-POL-01 | I18: ='E-Cliente'!H7 -> Asegurar que los datos requeridos sean válidos a nivel de tipo de dato, formato, rango, longitud y obligatoriedad. | J18: Generar una excepción indicando que se violó la regla: el correo y el teléfono deben ser obligatorios y tener formato válido. | K18: Detener operación
H19: ='E-Cliente'!G8 -> CLI-POL-02 | I19: ='E-Cliente'!H8 -> El correo electrónico ingresado no debe existir previamente en el sistema (Combinación única 1). | J19: Generar excepción indicando que el correo ingresado ya se encuentra registrado por otro usuario. | K19: Detener operación
H20: ='E-Cliente'!G9 -> CLI-POL-03 | I20: ='E-Cliente'!H9 -> La combinación de tipo de documento y número de documento no debe existir previamente en el sistema (Combinación única 2). | J20: Generar excepción indicando que el documento ya está registrado por otro usuario. | K20: Detener operación
A21: ='E-Cliente'!B10 -> Modificar datos del cliente | B21: {='E-Cliente'!C10:C10} -> Actualizar la información personal de contacto (teléfono o nombre) del usuario registrado en el sistema. | C21: clienteModificado | D21: Cliente | E21: Contiene la nueva información del cliente a actualizar. | F21: Logico | G21: Retorna verdadero si la información se actualizó con éxito en la base de datos. | H21: ='E-Cliente'!G10 -> CLI-POL-04 | I21: ='E-Cliente'!H10 -> El identificador del cliente (idCliente) proporcionado debe existir obligatoriamente en el sistema. | J21: Generar excepción indicando que el cliente que se intenta modificar no existe. | K21: Detener operación
A22: ='E-Cliente'!B11 -> Consultar listado de clientes | B22: ='E-Cliente'!C11 -> Listar en el panel de control todos los usuarios registrados para gestión operativa y soporte. | C22: filtros | D22: Texto | E22: Parámetros opcionales para filtrar la búsqueda de clientes. | F22: Lista<Cliente> | G22: Retorna una colección con los objetos de los clientes encontrados. | H22: ='E-Cliente'!G11 -> CLI-POL-05 | I22: ='E-Cliente'!H11 -> El administrador que ejecuta la acción debe tener una sesión válida y activa en el sistema. | J22: Generar excepción indicando acceso denegado por falta de permisos administrativos | K22: Detener operación

Sheet E-Cliente
A1: << Ir al modelo de dominio | E1: << Ir al listado de objetos de dominio | I1: << Ir a la caracterización del objeto de dominio
A2: Objeto de Dominio: | B2: =ListadoObjetosDominio!B3 -> Cliente
A3: Descripción: | B3: =ListadoObjetosDominio!C3 -> Objeto de dominio que representa a cada uno de los usuarios registrados que realizan compras en la plataforma de Imexcol.
A4: Actor | B4: Action/Command | D4: Entity/Aggregate/Object domain | E4: Read Model | G4: Business Rule/Policy | I4: External System | J4: Domain Event | K4: Hotspot/questions/Risk
A5: Actor | B5: Acción | C5: Descripción | D5: Objeto de dominio | E5: Información externa | G5: Políticas | I5: Sistema Externo | J5: Evento | K5: Aspectos por solucionar
E6: Información | F6: Descripción | G6: Número | H6: Descripción
A7: =ListadoObjetosDominio!B3 -> Cliente | B7: Registrar información del cliente | C7: Crear una nueva cuenta de usuario en la plataforma de comercio electrónico de Imexcol para poder realizar compras. | D7: =ListadoObjetosDominio!B3 -> Cliente | E7: tipoDocumento, numeroDocumento, nombre, correo, telefono | F7: Datos mínimos obligatorios requeridos por el sistema para identificar al usuario, facturar y contactarlo. | G7: CLI-POL-01 | H7: Asegurar que los datos requeridos sean válidos a nivel de tipo de dato, formato, rango, longitud y obligatoriedad. | I7: Base de datos | J7: Cliente registrado exitosamente | K7: Riesgo de que el usuario ingrese correos electrónicos temporales o falsos que reboten las facturas.
G8: CLI-POL-02 | H8: El correo electrónico ingresado no debe existir previamente en el sistema (Combinación única 1).
G9: CLI-POL-03 | H9: La combinación de tipo de documento y número de documento no debe existir previamente en el sistema (Combinación única 2).
A10: =_xlfn.CONCAT(ListadoObjetosDominio!B3,"/ ",ListadoObjetosDominio!B4,) -> Cliente/ Administrador | B10: Modificar datos del cliente | C10: Actualizar la información personal de contacto (teléfono o nombre) del usuario registrado en el sistema. | D10: =ListadoObjetosDominio!B3 -> Cliente | E10: idCliente, nombre, telefono | F10: Información editable del perfil del usuario para mantener el contacto actualizado en futuros despachos. | G10: CLI-POL-04 | H10: El identificador del cliente (idCliente) proporcionado debe existir obligatoriamente en el sistema. | I10: Base de datos | J10: Datos de cliente modificados | K10: Un administrador podría cambiar por error el teléfono de un cliente justo antes de un despacho logístico.
A11: =ListadoObjetosDominio!B4 -> Administrador | B11: Consultar listado de clientes | C11: Listar en el panel de control todos los usuarios registrados para gestión operativa y soporte. | D11: =ListadoObjetosDominio!B3 -> Cliente | E11: idCliente, tipoDocumento, numeroDocumento, nombre, correo, telefono | F11: Visualización tabular completa de los datos del cliente para que el administrador pueda auditar el registro. | G11: CLI-POL-05 | H11: El administrador que ejecuta la acción debe tener una sesión válida y activa en el sistema. | I11: Base de datos | J11: Listado de clientes consultado | K11: Si la base de datos crece a miles de clientes, la consulta sin paginación podría saturar la memoria del servidor (TimeOut).

Sheet P-Cliente 
A1: << Ir al modelo de dominio | E1: << Ir al listado de objetos de dominio | I1: << Ir a la caracterización del objeto de dominio
A2: Objeto de Dominio: | B2: =ListadoObjetosDominio!B3 -> Cliente
A3: Descripción: | B3: =ListadoObjetosDominio!C3 -> Objeto de dominio que representa a cada uno de los usuarios registrados que realizan compras en la plataforma de Imexcol.
A4: Business Rule/Policy
A5: Políticas
A6: Número | B6: Descripción
A7: CLI-POL-01 | B7: Asegurar que los datos requeridos sean válidos a nivel de tipo de dato, formato, rango, longitud y obligatoriedad.
A8: CLI-POL-02 | B8: El correo electrónico ingresado no debe existir previamente en el sistema (Combinación única 1).
A9: CLI-POL-03 | B9: La combinación de tipo de documento y número de documento no debe existir previamente en el sistema (Combinación única 2).
A10: CLI-POL-04 | B10: El identificador del cliente (idCliente) proporcionado debe existir obligatoriamente en el sistema.
A11: CLI-POL-05 | B11: El administrador que ejecuta la acción debe tener una sesión válida y activa en el sistema.

Sheet M-Administrador
A1: << Ir al modelo de dominio | D1: << Ir al listado de objetos de dominio | G1: << Ir a la caracterización del objeto de dominio
A2: Nombre | B2: =ListadoObjetosDominio!B4 -> Administrador
A3: Descripción | B3: =ListadoObjetosDominio!C4 -> Objeto de dominio que representa al personal interno encargado de gestionar el catálogo, los pedidos y la operación general del sistema.
A4: Identificador único universal (UUID) del administrador. | B4: Nombre de usuario único del administrador para iniciar sesión. | C4: Correo electrónico de contacto del administrador. | D4: Contraseña del administrador almacenada de forma segura. | E4: Indica que no pueden existir dos administradores o más con el mismo nombre de usuario.
A5: id | B5: nombreUsuario | C5: correoElectronico | D5: contrasena | E5: combinacion unica 1
A6: A1B2C3D4-5566-4F77-8899-AABBCCDDEE01 | B6: admin | C6: admin@imexcol.com | D6: ******** | E6: =B6 -> admin
A7: A1B2C3D4-5566-4F77-8899-AABBCCDDEE02 | B7: lmartinez | C7: l.martinez@imexcol.com | D7: ******** | E7: =B7 -> lmartinez
A8: A1B2C3D4-5566-4F77-8899-AABBCCDDEE03 | B8: sgomez | C8: s.gomez@imexcol.com | D8: ******** | E8: =B8 -> sgomez
A9: A1B2C3D4-5566-4F77-8899-AABBCCDDEE04 | B9: alopez | C9: a.lopez@imexcol.com | D9: ******** | E9: =B9 -> alopez
A10: A1B2C3D4-5566-4F77-8899-AABBCCDDEE05 | B10: mcastro | C10: m.castro@imexcol.com | D10: ******** | E10: =B10 -> mcastro
A13: Corresponde a los datos generales del objeto de dominio (nombre, descripción)
A14: Corresponde a las descripciones de los atributos
A15: Coresponde al nombre de los atributos
A16: Corresponde a los datos que son de libre ingreso
A17: Corresponde a los datos que se generarán automáticamente (IdAdmin)
A18: Corresponde a la combinación única 1

Sheet C-Administrador
A1: << Ir al modelo de dominio | D1: << Ir al listado de objetos de dominio | G1: << Ir a la caracterización del objeto de dominio
A2: Nombre | B2: ='M-Administrador'!B2 -> Administrador
A3: Descripción | B3: ='M-Administrador'!B3 -> Objeto de dominio que representa al personal interno encargado de gestionar el catálogo, los pedidos y la operación general del sistema.
A4: Nombre atributo | B4: Descripción atributo | C4: Identificador del objeto de dominio | D4: Tipo de dato | E4: Obligatorio | F4: Longitud minima(si aplica longitud maxima(si aplica) | G4: Longitud maxima(si aplica longitud maxima(si aplica) | H4: Precisión (si aplica) | I4: Redondeo(si aplica) | J4: Rango inicial(si aplica) | K4: Rango final (si aplica) | L4: Formato(Si aplica) | M4: Reglas especiales(si aplica) | N4: Dato calculado | O4: Aplica ajuste del dato(si aplica) | P4: Carácter de ajuste(si aplica) | Q4: Quitar espacios en blanco al inicio(si aplica) | R4: Quitar espacios en blanco al fin(si aplica) | S4: Dato sensible(si aplica) | T4: Valor por defecto(si aplica) | U4: Auto generado
A5: ='M-Administrador'!A5 -> id | B5: ='M-Administrador'!A4 -> Identificador único universal (UUID) del administrador. | C5: Si | D5: Alfanumerico | E5: Si | J5: 1 | K5: 999999 | M5: Identificador secuencial del administrador | N5: No | S5: No | U5: Si
A6: ='M-Administrador'!B5 -> nombreUsuario | B6: ='M-Administrador'!B4 -> Nombre de usuario único del administrador para iniciar sesión. | C6: No | D6: Alfanumerico | E6: Si | F6: 5 | G6: 50 | L6: Minusculas | M6: No debe contener espacios ni caracteres especiales | N6: No | O6: No | Q6: Si | R6: Si | S6: No | U6: No
A7: ='M-Administrador'!C5 -> correoElectronico | B7: ='M-Administrador'!C4 -> Correo electrónico de contacto del administrador. | C7: No | D7: Alfanumerico | E7: Si | F7: 8 | G7: 150 | M7: Debe almacenarse encriptada por seguridad del sistema | N7: No | O7: No | Q7: No | R7: No | S7: Si | U7: No
A9: Nombre combinación unica | B9: Descripción | C9: Atributos involucrados
A10: ='M-Administrador'!E5 -> combinacion unica 1 | B10: ='M-Administrador'!D4 -> Contraseña del administrador almacenada de forma segura. | C10: ='M-Administrador'!B5 -> nombreUsuario
A12: Responsabilidad | B12: Descripción | C12: Entradas | F12: Salida | H12: Políticas (Reglas de Negocio) | J12: Excepción
C13: Parámettro | D13: Tipo de dato | E13: Descripci | F13: Tipo de Dato | G13: Descripción | H13: Política | I13: Descripción | J13: Detalle | K13: ¿Qué hago?
A14: ='E-Administrador'!B7 -> Registrar nuevo administrador | B14: ='E-Administrador'!C7 -> Crear un nuevo usuario con credenciales para que un empleado pueda ingresar al panel de control de Imexcol. | C14: adminNuevo | D14: Administrador | E14: Contiene la información del administrador que se va a registrar. | F14: Logico | G14: Retorna verdadero si el administrador se registró correctamente. | H14: ='E-Administrador'!G7 -> ADM-POL-01 | I14: ='E-Administrador'!H7 -> Asegurar que los datos requeridos sean válidos a nivel de tipo de dato, formato, rango, longitud y obligatoriedad | J14: Generar excepción indicando qué campo no cumple con el formato o es obligatorio. | K14: Detener operación
H15: ='E-Administrador'!G8 -> ADM-POL-02 | I15: ='E-Administrador'!H8 -> El nombre de usuario ingresado no debe existir previamente en el sistema (Combinación única 1). | J15: Generar excepción indicando que el nombre de usuario ya se encuentra en uso por otro empleado. | K15: Detener operación
A17: ='E-Administrador'!B9 -> Modificar contraseña | B17: ='E-Administrador'!C9 -> Actualizar la clave de acceso de un administrador existente por motivos de seguridad o bloqueo. | C17: adminModificado | D17: Administrador | E17: Contiene el identificador y la nueva credencial a actualizar. | F17: Logico | G17: Retorna verdadero si la contraseña se actualizó con éxito en la base de datos. | H17: ='E-Administrador'!G9 -> ADM-POL-03 | I17: ='E-Administrador'!H9 -> El idAdmin proporcionado debe existir obligatoriamente en el sistema. | J17: Generar excepción indicando que el administrador que se intenta modificar no existe. | K17: Detener operación
A18: ='E-Administrador'!B10 -> Eliminar administrador | B18: ='E-Administrador'!C10 -> Revocar el acceso de un empleado al sistema eliminando su registro de la base de datos | C18: idAdmin | D18: alfanumerico | E18: Identificador exacto del administrador al que se le retirarán los privilegios. | F18: Logico | G18: Retorna verdadero si el administrador fue eliminado correctamente. | H18: ='E-Administrador'!G10 -> ADM-POL-04 | I18: ='E-Administrador'!H10 -> El idAdmin a eliminar debe existir previamente en la base de datos. | J18: Generar excepción indicando que el administrador a eliminar no se encuentra registrado. | K18: Detener operación
H19: ='E-Administrador'!G11 -> ADM-POL-05 | I19: ='E-Administrador'!H11 -> El sistema debe impedir la eliminación si el usuario a borrar es el único administrador restante en la base de datos. | J19: Generar excepción indicando que no se puede eliminar al último administrador del sistema. | K19: Detener operación
A20: ='E-Administrador'!B12 -> Iniciar sesión (Autenticar) | B20: ='E-Administrador'!C12 -> Validar las credenciales del empleado para otorgarle acceso seguro al panel de control del e-commerce | C20: credenciales | D20: Administrador | E20: Contiene el usuario y la contraseña que el empleado intenta validar. | F20: Logico | G20: Retorna verdadero si la autenticación fue exitosa. | H20: ='E-Administrador'!G12 -> ADM-POL-06 | I20: ='E-Administrador'!H12 -> El usuario y la contraseña ingresados deben coincidir exactamente con un registro existente en la base de datos. | J20: Generar excepción indicando que el nombre de usuario o la contraseña son incorrectos. | K20: Detener operación
A21: ='E-Administrador'!B13 -> Consultar administradores | B21: ='E-Administrador'!C13 -> Listar todos los empleados que actualmente tienen acceso al panel administrativo del e-commerce. | C21: filtros | D21: Texto | E21: Parámetros opcionales para filtrar la búsqueda de empleados. | F21: Lista<Administrador> | G21: Retorna una colección con los objetos de los administradores encontrados. | H21: ='E-Administrador'!G13 -> ADM-POL-07 | I21: ='E-Administrador'!H13 -> El administrador que ejecuta la consulta debe contar con una sesión activa en el sistema. | J21: Generar excepción indicando acceso denegado por sesión inactiva o falta de permisos. | K21: Detener operación

Sheet E-Administrador
A1: << Ir al modelo de dominio | E1: << Ir al listado de objetos de dominio | I1: << Ir a la caracterización del objeto de dominio
A2: Objeto de Dominio: | B2: =ListadoObjetosDominio!B4 -> Administrador
A3: Descripción: | B3: =ListadoObjetosDominio!C4 -> Objeto de dominio que representa al personal interno encargado de gestionar el catálogo, los pedidos y la operación general del sistema.
A4: Actor | B4: Action/Command | D4: Entity/Aggregate/Object domain | E4: Read Model | G4: Business Rule/Policy | I4: External System | J4: Domain Event | K4: Hotspot/questions/Risk
A5: Actor | B5: Acción | C5: Descripción | D5: Objeto de dominio | E5: Información externa | G5: Políticas | I5: Sistema Externo | J5: Evento | K5: Aspectos por solucionar
E6: Información | F6: Descripción | G6: Número | H6: Descripción
A7: =ListadoObjetosDominio!B4 -> Administrador | B7: Registrar nuevo administrador | C7: Crear un nuevo usuario con credenciales para que un empleado pueda ingresar al panel de control de Imexcol. | D7: =ListadoObjetosDominio!B4 -> Administrador | E7: usuario, password | F7: Credenciales de acceso requeridas para autenticar al nuevo empleado en el sistema. | G7: ADM-POL-01 | H7: Asegurar que los datos requeridos sean válidos a nivel de tipo de dato, formato, rango, longitud y obligatoriedad | I7: Base de datos | J7: Administrador registrado | K7: Riesgo de que la contraseña asignada inicialmente sea muy débil o predecible (ej. 12345678).
G8: ADM-POL-02 | H8: El nombre de usuario ingresado no debe existir previamente en el sistema (Combinación única 1).
A9: =ListadoObjetosDominio!B4 -> Administrador | B9: Modificar contraseña | C9: Actualizar la clave de acceso de un administrador existente por motivos de seguridad o bloqueo. | D9: =ListadoObjetosDominio!B4 -> Administrador | E9: idAdmin, password | F9: Identificador del empleado y la nueva credencial de seguridad a actualizar. | G9: ADM-POL-03 | H9: El idAdmin proporcionado debe existir obligatoriamente en el sistema. | I9: Base de datos | J9: Contraseña de administrador modificada | K9: Contraseña de administrador modificada Si un administrador cambia la contraseña de otro sin autorización, podría generar un bloqueo operativo en la tienda.
A10: =ListadoObjetosDominio!B4 -> Administrador | B10: Eliminar administrador | C10: Revocar el acceso de un empleado al sistema eliminando su registro de la base de datos | D10: =ListadoObjetosDominio!B4 -> Administrador | E10: idAdmin | F10: Identificador exacto del empleado al que se le retirarán los privilegios de acceso. | G10: ADM-POL-04 | H10: El idAdmin a eliminar debe existir previamente en la base de datos. | I10: Base de datos | J10: Administrador eliminado | K10: Riesgo de que el último o único administrador del sistema sea eliminado, bloqueando el acceso total a la plataforma.
G11: ADM-POL-05 | H11: El sistema debe impedir la eliminación si el usuario a borrar es el único administrador restante en la base de datos.
A12: =ListadoObjetosDominio!B4 -> Administrador | B12: Iniciar sesión (Autenticar) | C12: Validar las credenciales del empleado para otorgarle acceso seguro al panel de control del e-commerce | D12: =ListadoObjetosDominio!B4 -> Administrador | E12: usuario, password | F12: Formulario de login donde el empleado ingresa sus credenciales de acceso. | G12: ADM-POL-06 | H12: El usuario y la contraseña ingresados deben coincidir exactamente con un registro existente en la base de datos. | I12: Sistema Auth | J12: Sesión de administrador iniciada | K12: Riesgo de ataques de fuerza bruta (intentar adivinar la clave repetidamente). ¿Se debería bloquear el usuario tras 3 intentos fallidos?
A13: =ListadoObjetosDominio!B4 -> Administrador | B13: Consultar administradores | C13: Listar todos los empleados que actualmente tienen acceso al panel administrativo del e-commerce. | D13: =ListadoObjetosDominio!B4 -> Administrador | E13: idAdmin, usuario | F13: Vista de auditoría para revisar quiénes tienen credenciales activas en el sistema. | G13: ADM-POL-07 | H13: El administrador que ejecuta la consulta debe contar con una sesión activa en el sistema. | I13: Base de datos | J13: Listado de administradores consultado | K13: Exposición de nombres de usuario a empleados que no deberían tener permisos de auditoría de personal.

Sheet P-Administrador
A1: << Ir al modelo de dominio | E1: << Ir al listado de objetos de dominio | I1: << Ir a la caracterización del objeto de dominio
A2: Objeto de Dominio: | B2: =ListadoObjetosDominio!B4 -> Administrador
A3: Descripción: | B3: =ListadoObjetosDominio!C4 -> Objeto de dominio que representa al personal interno encargado de gestionar el catálogo, los pedidos y la operación general del sistema.
A4: Business Rule/Policy
A5: Políticas
A6: Número | B6: Descripción
A7: ADM-POL-01 | B7: Asegurar que los datos requeridos sean válidos a nivel de tipo de dato, formato, rango, longitud y obligatoriedad
A8: ADM-POL-02 | B8: El nombre de usuario ingresado no debe existir previamente en el sistema (Combinación única 1).
A9: ADM-POL-03 | B9: El idAdmin proporcionado debe existir obligatoriamente en el sistema.
A10: ADM-POL-04 | B10: El idAdmin a eliminar debe existir previamente en la base de datos.
A11: ADM-POL-05 | B11: El sistema debe impedir la eliminación si el usuario a borrar es el único administrador restante en la base de datos.
A12: ADM-POL-06 | B12: El usuario y la contraseña ingresados deben coincidir exactamente con un registro existente en la base de datos.
A13: ADM-POL-07 | B13: El administrador que ejecuta la consulta debe contar con una sesión activa en el sistema.

Sheet M-Dirección
A1: << Ir al modelo de dominio | I1: << Ir al listado de objetos de dominio | L1: << Ir a la caracterización del objeto de dominio
A2: Nombre: | B2: =ListadoObjetosDominio!B5 -> Dirección
A3: Descripción: | B3: =ListadoObjetosDominio!C5 -> Objeto de dominio que representa la ubicación física y estructurada que registra un cliente para la entrega de sus productos o propósitos de facturación.
A4: Identificador único universal (UUID) de la dirección. | B4: Referencia al cliente al que pertenece esta dirección. | C4: Nomenclatura exacta de la dirección (calle, carrera, número). | D4: Ciudad o municipio donde se ubica la dirección. | E4: Departamento o estado donde se ubica la dirección. | F4: País donde se ubica la dirección. | G4: Código postal de la dirección (opcional). | H4: Indica que un cliente no puede registrar dos veces exactamente la misma dirección física
A5: id | B5: cliente | C5: calle | D5: ciudad | E5: departamento | F5: pais | G5: codigoPostal | H5: Combinación Unica 1
A6: D1234567-8901-4234-5678-90123456D001 | B6: 3F2504E0-4F89-11D3-9A0C-0305E82C3301 | C6: Calle 10 # 43-20 | D6: Medellín | E6: Antioquia | F6: Colombia | G6: 050021 | H6: =C6 -> Calle 10 # 43-20
A7: D1234567-8901-4234-5678-90123456D002 | B7: 3F2504E0-4F89-11D3-9A0C-0305E82C3302 | C7: Carrera 48 # 32-15 | D7: Envigado | E7: Antioquia | F7: Colombia | G7: 055422 | H7: =C7 -> Carrera 48 # 32-15
A8: D1234567-8901-4234-5678-90123456D003 | B8: 3F2504E0-4F89-11D3-9A0C-0305E82C3303 | C8: Carrera 15 # 85-30 | D8: Bogotá | E8: Cundinamarca | F8: Colombia | G8: 110221 | H8: =C8 -> Carrera 15 # 85-30
A9: D1234567-8901-4234-5678-90123456D004 | B9: 3F2504E0-4F89-11D3-9A0C-0305E82C3304 | C9: Avenida 6N # 24-10 | D9: Cali | E9: Valle del Cauca | F9: Colombia | G9: 760045 | H9: =C9 -> Avenida 6N # 24-10
A10: D1234567-8901-4234-5678-90123456D005 | B10: 3F2504E0-4F89-11D3-9A0C-0305E82C3305 | C10: Calle 84 # 51B-20 | D10: Barranquilla | E10: Atlántico | F10: Colombia | G10: 080020 | H10: =C10 -> Calle 84 # 51B-20
A13: Corresponde a los datos generales del objeto de dominio (nombre, descripción)
A14: Corresponde a las descripciones de los atributos
A15: Coresponde al nombre de los atributos
A16: Corresponde a los datos que son de libre ingreso
A17: Corresponde a los datos que se generarán automáticamente (IdDireccion, idCliente)
A18: Corresponde a la combinación única 1

Sheet C-Direccion
A1: << Ir al modelo de dominio | D1: << Ir al listado de objetos de dominio | G1: << Ir a la caracterización del objeto de dominio
A3: Nombre | B3: ='M-Dirección'!B2 -> Dirección
A4: Descripción | B4: ='M-Dirección'!B3 -> Objeto de dominio que representa la ubicación física y estructurada que registra un cliente para la entrega de sus productos o propósitos de facturación.
A5: Nombre atributo | B5: Descripción atributo | C5: Identificador del objeto de dominio | D5: Tipo de dato | E5: Obligatorio | F5: Longitud minima(si aplica longitud maxima(si aplica) | G5: Longitud maxima(si aplica longitud maxima(si aplica) | H5: Precisión (si aplica) | I5: Redondeo(si aplica) | J5: Rango inicial(si aplica) | K5: Rango final (si aplica) | L5: Formato(Si aplica) | M5: Reglas especiales(si aplica) | N5: Dato calculado | O5: Aplica ajuste del dato(si aplica) | P5: Carácter de ajuste(si aplica) | Q5: Quitar espacios en blanco al inicio(si aplica) | R5: Quitar espacios en blanco al fin(si aplica) | S5: Dato sensible(si aplica) | T5: Valor por defecto(si aplica) | U5: Auto generado | V5: Registrar una nueva categoría | W5: Consultar la información de las categorías | X5: Permite listar las categorías en la página web para filtrar y buscar productos. | Y5: Actualizar el nombre de una categoría | Z5: Eliminar una categoría
A6: ='M-Dirección'!A5 -> id | B6: ='M-Dirección'!A4 -> Identificador único universal (UUID) de la dirección. | C6: Si | D6: Alfanumerico | E6: Si | F6: 1 | L6: Mayusculas | N6: No | O6: No | Q6: Si | R6: Si | S6: No | U6: Si | V6: No requerido | W6: No Requerido | X6: No requerido | Y6: No requerido | Z6: No requerido
A7: ='M-Dirección'!B5 -> cliente | B7: ='M-Dirección'!B4 -> Referencia al cliente al que pertenece esta dirección. | C7: No | D7: <Cliente> | E7: Si | M7: Debe existir un cliente previamente registrado | N7: No | S7: No | U7: No | V7: Requerido | W7: Requerido | X7: Requerido | Y7: Requerido | Z7: Requerido
A8: ='M-Dirección'!C5 -> calle | B8: ='M-Dirección'!C4 -> Nomenclatura exacta de la dirección (calle, carrera, número). | C8: No | D8: Texto | E8: Si | F8: 4 | G8: 200 | L8: Capitalizado | M8: Solo nombres válidos de divisiones territoriales | N8: No | O8: No | Q8: Si | R8: Si | S8: No | U8: No
A9: ='M-Dirección'!D5 -> ciudad | B9: ='M-Dirección'!D4 -> Ciudad o municipio donde se ubica la dirección. | C9: No | D9: Texto | E9: Si | F9: 3 | G9: 100 | L9: Capitalizado | M9: Solo nombres válidos de municipios | N9: No | O9: No | Q9: Si | R9: Si | S9: No | U9: No
A10: ='M-Dirección'!E5 -> departamento | B10: ='M-Dirección'!E4 -> Departamento o estado donde se ubica la dirección. | C10: No | D10: Texto | E10: Si | F10: 5 | G10: 100 | M10: Formato de nomenclatura urbana estándar | N10: No | O10: No | Q10: Si | R10: Si | S10: No | U10: No
A11: ='M-Dirección'!F5 -> pais | B11: ='M-Dirección'!F4 -> País donde se ubica la dirección. | C11: No | D11: Texto | E11: Si | F11: 0 | G11: 100 | M11: Datos complementarios para ubicación | N11: No | O11: No | Q11: Si | R11: Si | S11: No | U11: No
A13: Nombre combinación unica | B13: Descripción | C13: Atributos involucrados
A14: ='M-Dirección'!G5 -> codigoPostal | B14: ='M-Dirección'!G4 -> Código postal de la dirección (opcional). | C14: {='M-Dirección'!E5:F5} -> departamento | D14: pais
A16: Responsabilidad | B16: Descripción | C16: Entradas | F16: Salida | H16: Políticas (Reglas de Negocio) | J16: Excepción
C17: Parámettro | D17: Tipo de dato | E17: Descripci | F17: Tipo de Dato | G17: Descripción | H17: Política | I17: Descripción | J17: Detalle | K17: ¿Qué hago?
A18: ='E-Direccion'!B7 -> Agregar dirección | B18: ='E-Direccion'!C7 -> Registrar una nueva ubicación física para la entrega de pedidos o facturación. | C18: direccionNueva | D18: Dirección | E18: Contiene la información de la nueva dirección a registrar. | F18: Logico | G18: Retorna verdadero si la dirección se agregó correctamente al perfil del cliente. | H18: ='E-Direccion'!G7 -> DIR-POL-01 | I18: ='E-Direccion'!H7 -> Asegurar que los datos requeridos sean válidos a nivel de tipo de dato, formato, longitud y obligatoriedad. | J18: Generar excepción indicando qué campo de la dirección no cumple con el formato o es obligatorio. | K18: Detener operación
H19: ='E-Direccion'!G8 -> DIR-POL-02 | I19: ='E-Direccion'!H8 -> El idCliente asociado debe existir previamente | J19: Generar excepción indicando que el cliente asociado a la dirección no existe en la base de datos. | K19: Detener operación
A21: ='E-Direccion'!B10 -> Modificar dirección | B21: ='E-Direccion'!C10 -> Actualizar los detalles de una dirección existente (ej. corrección de calle o apartamento). | C21: direccionModificada | D21: Dirección | E21: Contiene la nueva información de la ubicación a actualizar. | F21: Logico | G21: Retorna verdadero si la dirección se modificó exitosamente. | H21: ='E-Direccion'!G10 -> DIR-POL-04 | I21: ='E-Direccion'!H10 -> El idDireccion a modificar debe existir previamente en el sistema | J21: Generar excepción indicando que la dirección no existe o el usuario no tiene permisos para editarla. | K21: Detener operación
A22: ='E-Direccion'!B11 -> Eliminar dirección | B22: ='E-Direccion'!C11 -> Quitar una dirección de la libreta de direcciones del usuario para que no aparezca en futuras compras. | C22: idDireccion | D22: alfanumerico | E22: Identificador exacto de la ubicación que el usuario desea borrar. | F22: Logico | G22: Retorna verdadero si la dirección fue eliminada o inactivada correctamente. | H22: ='E-Direccion'!G11 -> DIR-POL-05 | I22: ='E-Direccion'!H11 -> El idDireccion a eliminar debe existir previamente en el sistema | J22: Generar excepción indicando que la dirección a borrar no existe o no es de su propiedad. | K22: Detener operación
H23: ='E-Direccion'!#REF! -> #REF! | I23: ='E-Direccion'!H12 -> 0 | J23: Generar excepción indicando que la dirección está bloqueada temporalmente porque tiene un envío en curso. | K23: Detener operación
A24: ='E-Direccion'!B13 -> 0 | B24: ='E-Direccion'!C11 -> Quitar una dirección de la libreta de direcciones del usuario para que no aparezca en futuras compras. | C24: idCliente | D24: alfanumerico | E24: Identificador del cliente del cual se quieren obtener las ubicaciones guardadas. | F24: Lista<Dirección> | G24: Retorna una colección con los objetos de las direcciones encontradas. | H24: ='E-Direccion'!G13 -> 0 | I24: ='E-Direccion'!H13 -> 0 | J24: Generar excepción indicando acceso denegado por intentar consultar direcciones de otro usuario sin rol de administrador. | K24: Detener operación

Sheet E-Direccion
A1: << Ir al modelo de dominio | D1: << Ir al listado de objetos de dominio | H1: << Ir a la caracterización del objeto de dominio | L1: Ir al muestreo de datos del objeto de dominio >>
A2: Objeto de Dominio: | B2: =ListadoObjetosDominio!B5 -> Dirección
A3: Descripción: | B3: =ListadoObjetosDominio!C5 -> Objeto de dominio que representa la ubicación física y estructurada que registra un cliente para la entrega de sus productos o propósitos de facturación.
A4: Actor | B4: Action/Command | D4: Entity/Aggregate/Object domain | E4: Read Model | G4: Business Rule/Policy | I4: External System | J4: Domain Event | K4: Hotspot/questions/Risk
A5: Actor | B5: Acción | C5: Descripción | D5: Objeto de dominio | E5: Información externa | G5: Políticas | I5: Sistema Externo | J5: Evento | K5: Aspectos por solucionar
E6: Información | F6: Descripción | G6: Número | H6: Descripción
A7: =ListadoObjetosDominio!B3 -> Cliente | B7: Agregar dirección | C7: Registrar una nueva ubicación física para la entrega de pedidos o facturación. | D7: =ListadoObjetosDominio!B5 -> Dirección | E7: idCliente, departamento, ciudad, calle, detalleAdicional | F7: Formulario de creación con los datos de ubicación vinculados al perfil del usuario. | G7: DIR-POL-01 | H7: Asegurar que los datos requeridos sean válidos a nivel de tipo de dato, formato, longitud y obligatoriedad. | I7: Base de datos | J7: Dirección agregada | K7: Riesgo de que el cliente ingrese una nomenclatura errónea que la transportadora no pueda encontrar
G8: DIR-POL-02 | H8: El idCliente asociado debe existir previamente
G9: DIR-POL-03 | H9: Un cliente no puede registrar dos direcciones con la misma combinación de calle, ciudad, departamento
A10: =ListadoObjetosDominio!B3 -> Cliente | B10: Modificar dirección | C10: Actualizar los detalles de una dirección existente (ej. corrección de calle o apartamento). | D10: =ListadoObjetosDominio!B5 -> Dirección | E10: idDireccion, departamento, ciudad, calle, detalleAdicional | F10: Formulario pre-poblado con la información actual de la dirección a editar. | G10: DIR-POL-04 | H10: El idDireccion a modificar debe existir previamente en el sistema | I10: Base de datos | J10: Dirección modificada | K10: ¿Qué pasa si el cliente modifica una dirección mientras un pedido en curso ya va en camino hacia la dirección anterior?
A11: Cliente | B11: Eliminar dirección | C11: Quitar una dirección de la libreta de direcciones del usuario para que no aparezca en futuras compras. | D11: =ListadoObjetosDominio!B5 -> Dirección | E11: idDireccion | F11: Identificador de la ubicación que el usuario desea borrar de su perfil. | G11: DIR-POL-05 | H11: El idDireccion a eliminar debe existir previamente en el sistema | I11: Base de datos | J11: Direccion eliminada | K11: Si se elimina físicamente la dirección, se puede dañar el historial de facturas pasadas.

Sheet P-Dirección
A1: << Ir al modelo de dominio | D1: << Ir al listado de objetos de dominio | H1: << Ir a la caracterización del objeto de dominio | L1: Ir al muestreo de datos del objeto de dominio >>
A2: Objeto de Dominio: | B2: =ListadoObjetosDominio!B5 -> Dirección
A3: Descripción: | B3: =ListadoObjetosDominio!C5 -> Objeto de dominio que representa la ubicación física y estructurada que registra un cliente para la entrega de sus productos o propósitos de facturación.
A4: Business Rule/Policy
A5: Políticas
A6: Número | B6: Descripción
A7: DIR-POL-01 | B7: Asegurar que los datos requeridos sean válidos a nivel de tipo de dato, formato, longitud y obligatoriedad.
A8: DIR-POL-02 | B8: El idCliente asociado debe existir previamente
A9: DIR-POL-03 | B9: Un cliente no puede registrar dos direcciones con la misma combinación de calle, ciudad, departamento
A10: DIR-POL-04 | B10: El idDireccion a modificar debe existir previamente en el sistema
A11: DIR-POL-05 | B11: El idDireccion a eliminar debe existir previamente en el sistema

Sheet M-Categoria
A1: << Ir al modelo de dominio | E1: << Ir al listado de objetos de dominio | H1: << Ir a la caracterización del objeto de dominio
A2: Nombre: | B2: =ListadoObjetosDominio!B6 -> Categoría
A3: Descripción: | B3: =ListadoObjetosDominio!C6 -> Objeto de dominio que representa a cada una de las agrupaciones taxonómicas en las que se organizan los productos del catálogo de Imexcol.
A4: Identificador único universal (UUID) de la categoría. | B4: Nombre comercial de la categoría de productos. | C4: Descripción breve de la categoría (opcional). | D4: Indica que no pueden existir dos categorías o más con el mismo nombre
A5: id | B5: nombre | C5: descripcion | D5: combinación unica 1
A6: CA111111-1111-4111-8111-111111111101 | B6: Hogar | C6: Productos decorativos y utilitarios para el hogar. | D6: =B6 -> Hogar
A7: CA111111-1111-4111-8111-111111111102 | B7: Moda | C7: Prendas de vestir y accesorios de moda. | D7: =B7 -> Moda
A8: CA111111-1111-4111-8111-111111111103 | B8: Accesorios | C8: Accesorios personales y complementos. | D8: =B8 -> Accesorios
A9: CA111111-1111-4111-8111-111111111104 | B9: Tecnología | C9: Dispositivos y accesorios tecnológicos. | D9: =B9 -> Tecnología
A10: CA111111-1111-4111-8111-111111111105 | B10: Cocina | C10: Utensilios y menaje de cocina. | D10: =B10 -> Cocina
A12: Corresponde a los datos generales del objeto de dominio (nombre, descripción)
A13: Corresponde a las descripciones de los atributos
A14: Coresponde al nombre de los atributos
A15: Corresponde a los datos que son de libre ingreso (referencia, nombre, descripcion, precio y estado)
A16: Corresponde a los datos que se generarán automáticamente (idCategoria)
A17: Corresponde a la combinación única 1

Sheet C-Categoria
A1: << Ir al modelo de dominio | D1: << Ir al listado de objetos de dominio | G1: << Ir a la caracterización del objeto de dominio
A3: Nombre | B3: ='M-Categoria'!B2 -> Categoría
A4: Descripción | B4: ='M-Categoria'!B3 -> Objeto de dominio que representa a cada una de las agrupaciones taxonómicas en las que se organizan los productos del catálogo de Imexcol.
A5: Nombre atributo | B5: Descripción atributo | C5: Identificador del objeto de dominio | D5: Tipo de dato | E5: Obligatorio | F5: Longitud minima(si aplica longitud maxima(si aplica) | G5: Longitud maxima(si aplica longitud maxima(si aplica) | H5: Precisión (si aplica) | I5: Redondeo(si aplica) | J5: Rango inicial(si aplica) | K5: Rango final (si aplica) | L5: Formato(Si aplica) | M5: Reglas especiales(si aplica) | N5: Dato calculado | O5: Aplica ajuste del dato(si aplica) | P5: Carácter de ajuste(si aplica) | Q5: Quitar espacios en blanco al inicio(si aplica) | R5: Quitar espacios en blanco al fin(si aplica) | S5: Dato sensible(si aplica) | T5: Valor por defecto(si aplica) | U5: Auto generado | V5: Registrar una nueva categoría | W5: Consultar la información de las categorías | X5: Permite listar las categorías en la página web para filtrar y buscar productos. | Y5: Actualizar el nombre de una categoría | Z5: Eliminar una categoría
A6: ='M-Categoria'!A5 -> id | B6: ='M-Categoria'!A4 -> Identificador único universal (UUID) de la categoría. | C6: Si | D6: Alfanumerico | E6: Si | F6: 3 | L6: Mayusculas | N6: No | O6: No | Q6: Si | R6: Si | S6: No | U6: Si | V6: No requerido | W6: No Requerido | X6: No requerido | Y6: No requerido | Z6: No requerido
A7: ='M-Categoria'!B5 -> nombre | B7: ='M-Categoria'!B4 -> Nombre comercial de la categoría de productos. | C7: No | D7: Alfanumerico | E7: Si | F7: 3 | G7: 100 | L7: Capitalizado | M7: Nombre comercial de la categoría | N7: No | O7: No | Q7: Si | R7: Si | S7: No | T7: Activo | U7: No | V7: Requerido | W7: Requerido | X7: Requerido | Y7: Requerido | Z7: Requerido
A8: ='M-Categoria'!C5 -> descripcion | B8: ='M-Categoria'!C4 -> Descripción breve de la categoría (opcional). | C8: No | D8: Texto | E8: No | G8: 255 | L8: N/A | M8: Solo permite valores 'Activo' o 'Inactivo' | N8: No | O8: No | Q8: Si | R8: Si | S8: No | T8: Activo | U8: No
A10: Nombre combinación unica | B10: Descripción | C10: Atributos involucrados
A11: ='M-Categoria'!D5 -> combinación unica 1 | B11: ='M-Categoria'!D4 -> Indica que no pueden existir dos categorías o más con el mismo nombre | C11: ='M-Categoria'!B5 -> nombre
A13: Responsabilidad | B13: Descripción | C13: Entradas | F13: Salida | H13: Políticas (Reglas de Negocio) | J13: Excepción
C14: Parámettro | D14: Tipo de dato | E14: Descripci | F14: Tipo de Dato | G14: Descripción | H14: Política | I14: Descripción | J14: Detalle | K14: ¿Qué hago?
A15: ='E-Categoria'!B7 -> Crear Categoria | B15: ='E-Categoria'!C7 -> Permite ingresar al sistema una nueva categoría para agrupar los productos del catálogo. | C15: categoriaNueva | D15: Categoría | E15: Contiene la información de la nueva categoría a registrar. | F15: Logico | G15: Retorna verdadero si la categoría se agregó correctamente al sistema. | H15: ='E-Categoria'!G7 -> CAT-POL-01 | I15: ='E-Categoria'!H7 -> Asegurar que los datos requeridos sean válidos a nivel de tipo de dato, formato, longitud y obligatoriedad. | J15: Generar excepción indicando qué campo no cumple con el formato o es obligatorio. | K15: Detener operación
H16: ='E-Categoria'!G8 -> CAT-POL-02 | I16: ='E-Categoria'!H8 -> El nombre de la categoría debe ser único en el sistema para evitar duplicidad. | J16: Generar excepción indicando que ya existe otra categoría registrada con ese mismo nombre. | K16: Detener operación
A17: ='E-Categoria'!B9 -> Modificar categoría | B17: ='E-Categoria'!C9 -> Actualizar los detalles de una categoría existente (ej. corregir ortografía o ampliar la descripción). | C17: ategoriaModificada | D17: Categoría | E17: Contiene la nueva información de la categoría a actualizar. | F17: Logico | G17: Retorna verdadero si la categoría se modificó exitosamente. | H17: ='E-Categoria'!G9 -> CAT-POL-03 | I17: ='E-Categoria'!H9 -> El idCategoria a modificar debe existir previamente en el sistema. | J17: Generar excepción indicando que la categoría que se intenta modificar no existe en la base de datos. | K17: Detener operación
A18: ='E-Categoria'!B10 -> Eliminar categoría | B18: ='E-Categoria'!C10 -> Quitar una categoría del catálogo para que ya no esté disponible en la tienda. | C18: idCategoria | D18: alfanumerico | E18: Identificador exacto de la categoría que se desea borrar. | F18: Logico | G18: Retorna verdadero si la categoría fue eliminada correctamente. | H18: ='E-Categoria'!G10 -> CAT-POL-04 | I18: ='E-Categoria'!H10 -> El idCategoria a eliminar debe existir previamente en el sistema. | J18: Generar excepción indicando que la categoría a borrar no se encuentra registrada. | K18: Detener operación
H19: ='E-Categoria'!G11 -> CAT-POL-05 | I19: ='E-Categoria'!H11 -> El sistema debe impedir la eliminación de la categoría si esta tiene uno o más productos asociados actualmente. | J19: Generar excepción indicando que la categoría está en uso por productos existentes y no puede ser eliminada. | K19: Detener operación
A20: ='E-Categoria'!B12 -> Consultar categorías | B20: ='E-Categoria'!C12 -> Listar las categorías disponibles para desplegarlas en el menú de navegación o panel administrativo. | C20: filtros | D20: Texto | E20: Parámetros opcionales para filtrar la búsqueda de categorías. | F20: Lista<Categoría> | G20: Retorna una colección con los objetos de las categorías encontradas. | H20: ='E-Categoria'!G12 -> CAT-POL-06 | I20: ='E-Categoria'!H12 -> Asegurar que los datos requeridos sean válidos a nivel de tipo de dato, formato, longitud y obligatoriedad. | J20: Generar excepción indicando que los parámetros de búsqueda tienen un formato incorrecto. | K20: Detener operación

Sheet E-Categoria
A1: << Ir al modelo de dominio | D1: << Ir al listado de objetos de dominio | H1: << Ir a la caracterización del objeto de dominio | L1: Ir al muestreo de datos del objeto de dominio >>
A2: Objeto de Dominio: | B2: =ListadoObjetosDominio!B6 -> Categoría
A3: Descripción: | B3: =ListadoObjetosDominio!C6 -> Objeto de dominio que representa a cada una de las agrupaciones taxonómicas en las que se organizan los productos del catálogo de Imexcol.
A4: Actor | B4: Action/Command | D4: Entity/Aggregate/Object domain | E4: Read Model | G4: Business Rule/Policy | I4: External System | J4: Domain Event | K4: Hotspot/questions/Risk
A5: Actor | B5: Acción | C5: Descripción | D5: Objeto de dominio | E5: Información externa | G5: Políticas | I5: Sistema Externo | J5: Evento | K5: Aspectos por solucionar
E6: Información | F6: Descripción | G6: Número | H6: Descripción
A7: Administrador | B7: Crear Categoria | C7: Permite ingresar al sistema una nueva categoría para agrupar los productos del catálogo. | D7: =ListadoObjetosDominio!B6 -> Categoría | E7: nombre, descripcion | F7: Formulario para ingresar el nombre y detalles de la nueva familia de productos. | G7: CAT-POL-01 | H7: Asegurar que los datos requeridos sean válidos a nivel de tipo de dato, formato, longitud y obligatoriedad. | I7: Base de datos | J7: Categoría creada | K7: Riesgo de crear categorías duplicadas o con nombres muy similares que confundan al cliente.
G8: CAT-POL-02 | H8: El nombre de la categoría debe ser único en el sistema para evitar duplicidad.
A9: Administrador | B9: Modificar categoría | C9: Actualizar los detalles de una categoría existente (ej. corregir ortografía o ampliar la descripción). | D9: =ListadoObjetosDominio!B6 -> Categoría | E9: idCategoria, nombre, descripcion | F9: Formulario pre-poblado con la información actual de la categoría a editar. | G9: CAT-POL-03 | H9: El idCategoria a modificar debe existir previamente en el sistema. | I9: Base de datos | J9: Categoría modificada | K9: Cambiar el nombre drásticamente podría desorientar a los clientes que buscan productos específicos.
A10: Administrador | B10: Eliminar categoría | C10: Quitar una categoría del catálogo para que ya no esté disponible en la tienda. | D10: =ListadoObjetosDominio!B6 -> Categoría | E10: idCategoria | F10: Identificador de la agrupación que el administrador desea retirar. | G10: CAT-POL-04 | H10: El idCategoria a eliminar debe existir previamente en el sistema. | I10: Base de datos | J10: Categoría eliminada | K10: Riesgo crítico: dejar productos "huérfanos". ¿Qué pasa con los productos si se borra su categoría?
G11: CAT-POL-05 | H11: El sistema debe impedir la eliminación de la categoría si esta tiene uno o más productos asociados actualmente.
A12: Cliente / Administrador | B12: Consultar categorías | C12: Listar las categorías disponibles para desplegarlas en el menú de navegación o panel administrativo. | D12: Categoría | E12: idCategoria, nombre, descripcion | F12: Menú visual en la tienda web o grilla en el panel de control del administrador. | G12: CAT-POL-06 | H12: Asegurar que los datos requeridos sean válidos a nivel de tipo de dato, formato, longitud y obligatoriedad. | I12: Base de datos | J12: Categorías consultadas | K12: Si hay demasiadas categorías cargadas al mismo tiempo, el menú principal podría volverse inmanejable.

Sheet P-Categoría
A1: << Ir al modelo de dominio | D1: << Ir al listado de objetos de dominio | H1: << Ir a la caracterización del objeto de dominio | L1: Ir al muestreo de datos del objeto de dominio >>
A2: Objeto de Dominio: | B2: =ListadoObjetosDominio!B6 -> Categoría
A3: Descripción: | B3: =ListadoObjetosDominio!C6 -> Objeto de dominio que representa a cada una de las agrupaciones taxonómicas en las que se organizan los productos del catálogo de Imexcol.
A4: Business Rule/Policy
A5: Políticas
A6: Número | B6: Descripción
A7: CAT-POL-01 | B7: Asegurar que los datos requeridos sean válidos a nivel de tipo de dato, formato, longitud y obligatoriedad.
A8: CAT-POL-02 | B8: El nombre de la categoría debe ser único en el sistema para evitar duplicidad.
A9: CAT-POL-03 | B9: El idCategoria a modificar debe existir previamente en el sistema.
A10: CAT-POL-04 | B10: El idCategoria a eliminar debe existir previamente en el sistema.
A11: CAT-POL-05 | B11: El sistema debe impedir la eliminación de la categoría si esta tiene uno o más productos asociados actualmente.
A12: CAT-POL-06 | B12: Asegurar que los datos requeridos sean válidos a nivel de tipo de dato, formato, longitud y obligatoriedad.

Sheet M-Producto
A1: <<< Ir al modelo de dominio | D1: << Ir al listado de objetos de dominio | G1: << Ir a la caracterización del objeto de dominio
A2: Nombre | B2: =ListadoObjetosDominio!B7 -> Producto
A3: Descripción | B3: =ListadoObjetosDominio!C7 -> Objeto de dominio que representa a cada uno de los artículos de importación (bolsos, juguetes, etc.) que están disponibles para la venta en la tienda.
A4: Identificador único universal (UUID) del producto. | B4: Referencia a la categoría a la que pertenece el producto. | C4: Nombre comercial del producto. | D4: Descripción detallada de las características del producto. | E4: Precio del producto en pesos colombianos (COP). | F4: Cantidad de unidades disponibles en inventario. | G4: Ruta relativa a la imagen representativa del producto (opcional). | H4: Indica que no pueden existir dos productos o más con la misma referencia en el sistema.
A5: id | B5: categoria | C5: nombre | D5: descripcion | E5: precio | F5: stock | G5: imagenUrl | H5: CombinacionUnica1
A6: 4F8A0001-2222-4333-8444-555566667701 | B6: CA111111-1111-4111-8111-111111111101 | C6: Lámpara decorativa NP5115 | D6: Lámpara de mesa decorativa con base metálica y pantalla en tela. | E6: 89900 | F6: 25 | G6: img/Lampara_NP5115.png | H6: =A6 -> 4F8A0001-2222-4333-8444-555566667701
A7: 4F8A0001-2222-4333-8444-555566667702 | B7: CA111111-1111-4111-8111-111111111103 | C7: Sombrilla antiviento NP4292 | D7: Sombrilla plegable antiviento con forro reforzado y mango ergonómico. | E7: 145000 | F7: 40 | G7: img/Sombrilla_antiviento_NP4292.png | H7: =A7 -> 4F8A0001-2222-4333-8444-555566667702
A8: 4F8A0001-2222-4333-8444-555566667703 | B8: CA111111-1111-4111-8111-111111111102 | C8: Gorra para hombre NP5275 | D8: Gorra deportiva para hombre con visera curva y ajuste trasero. | E8: 35500 | F8: 60 | G8: img/Gorra_hombre_NP5275.png | H8: =A8 -> 4F8A0001-2222-4333-8444-555566667703
A9: 4F8A0001-2222-4333-8444-555566667704 | B9: CA111111-1111-4111-8111-111111111105 | C9: Set de cucharas inoxidables x 12 | D9: Set de 12 cucharas en acero inoxidable con diseño labrado. | E9: 32000 | F9: 0 | G9: img/Set_Cucharas_NP712.png | H9: =A9 -> 4F8A0001-2222-4333-8444-555566667704
A10: 4F8A0001-2222-4333-8444-555566667705 | B10: CA111111-1111-4111-8111-111111111104 | C10: Audífonos inalámbricos | D10: Audífonos bluetooth con cancelación de ruido y estuche de carga. | E10: 189900 | F10: 15 | G10: img/Audifonos_inalam_NP0314.png | H10: =A10 -> 4F8A0001-2222-4333-8444-555566667705
A13: Corresponde a los datos generales del objeto de dominio (nombre, descripción)
A14: Corresponde a las descripciones de los atributos
A15: Coresponde al nombre de los atributos
A16: Corresponde a los datos que son de libre ingreso (referencia, nombre, descripcion, precio y estado)
A17: Corresponde a referencias a otros objetos de dominio (idCategoria)
A18: Corresponde a los datos que se generarán automáticamente (idProducto)
A19: Corresponde a la combinación única 1

Sheet C-Producto
A1: << Ir al modelo de dominio | D1: << Ir al listado de objetos de dominio | G1: << Ir a la caracterización del objeto de dominio
A2: Nombre | B2: ='M-Producto'!B2 -> Producto
A3: Descripción | B3: ='M-Producto'!B3 -> Objeto de dominio que representa a cada uno de los artículos de importación (bolsos, juguetes, etc.) que están disponibles para la venta en la tienda.
